Workbook

Sheet Instructions
B1: Furnace predictive maintenance checksheet
B2: Mass Wire and Steels Pvt. Ltd. · Bhiwadi · pusher furnaces F-01 … F-04
B4: Why predictive
B5: Instead of only checking that equipment works, the same values are measured every day (pressures, motor currents, vibration, temperatures, controller output, wall difference). A slow change in a value warns of a failure weeks before it happens, so the work can be planned for a stop instead of a breakdown with product inside the furnace.
B7: Sheets
B8: Parameters – the list of what is measured, how, the normal value and the watch / act limits. One list for all furnaces; items for one furnace only (F-01 water quench, F-02 oil quench) say so in 'Applies to'.
B9: Daily checksheet – form F-MT-01, one per furnace per day. Status per item: OK, WATCH (beyond the watch limit) or ACT (beyond the action limit / check Not OK), and a result for the day.
B10: Monthly trend – form F-MT-02, one per furnace per month: the daily readings of 10 key parameters, the trend per day and the estimated days until the action limit.
B11: Example daily (F-02) / Example trend (F-02) – the forms filled in, showing a rising pusher pressure, rising blower vibration and a falling agitator current.
B13: How to fill in
B14: • Fill only the yellow cells; grey cells are calculated. Choose the furnace first: items for another furnace turn grey and show N/A (F-03 and F-04 have no quench).
B15: • Take readings at the same point, with the same instrument, at the same furnace condition every day (steady state for currents, outputs and wall difference) – otherwise the trend means nothing.
... B26: Calculated cell (grey)

Sheet Daily checksheet
A1: Mass Wire and Steels Pvt. Ltd. · Bhiwadi · Heat treatment maintenance
A2: Daily predictive maintenance checksheet – furnace | K2: Form F-MT-01 · Rev 0
K3: One sheet per furnace per day
B5: Furnace | F5: Date | J5: Shift
B6: Furnace state | F6: Checked by | J6: Instruments used
A7: Take the readings at the same time and place every day, with the furnace at steady state where the item says so. Enter yesterday's reading to see the change (or copy it from yesterday's sheet).
A9: No. | B9: Area | C9: Parameter | D9: Method / instrument | E9: Unit | F9: Limits | G9: Normal | H9: Reading today | I9: Reading yesterday | J9: Change since yesterday | K9: vs normal | L9: Status | M9: Action / remarks (work order no.) | N9: Applicable
A10: =Parameters!$A$5 -> 1 | B10: =Parameters!$B$5 -> Combustion | C10: =Parameters!$C$5 -> Main gas pressure at the furnace gas train | D10: =Parameters!$D$5 -> Gas train gauge | E10: =IF(Parameters!$E$5="","",Parameters!$E$5) -> mbar | F10: =IF(Parameters!$F$5="Check","OK / Not OK",TRIM(IF(Parameters!$I$5<>"","act <"&Parameters!$I$5&" ","")&IF(Parameters!$J$5<>"","watch <"&Parameters!$J$5&" ","")&IF(Parameters!$K$5<>"","watch >"&Parameters!$K$5&" ","")&IF(Parameters!$L$5<>"","act >"&Parameters!$L$5,""))) -> act <30 watch <34 watch >46 act >50 | G10: =IF(Parameters!$H$5="","",Parameters!$H$5) -> 40 | J10: =IF(OR(H10="",I10="",Parameters!$F$5="Check"),"",H10-I10) | K10: =IF(OR(H10="",G10="",Parameters!$F$5="Check"),"",IF(G10=0,H10-G10,(H10-G10)/ABS(G10))) | L10: =IF(LEFT(N10,2)="No","N/A",IF(H10="","",IF(Parameters!$F$5="Check",IF(H10="OK","OK","ACT"),IF(OR(AND(Parameters!$I$5<>"",H10<Parameters!$I$5),AND(Parameters!$L$5<>"",H10>Parameters!$L$5)),"ACT",IF(OR(AND(Parameters!$J$5<>"",H10<Parameters!$J$5),AND(Parameters!$K$5<>"",H10>Parameters!$K$5)),"WATCH","OK"))))) | N10: =IF(Parameters!$G$5="All","Yes",IF($C$5="","Yes",IF(ISNUMBER(SEARCH($C$5,Parameters!$G$5)),"Yes","No – N/A for "&$C$5))) -> Yes
A11: =Parameters!$A$6 -> 2 | B11: =Parameters!$B$6 -> Combustion | C11: =Parameters!$C$6 -> Combustion air pressure after the blower | D11: =Parameters!$D$6 -> Air header gauge | E11: =IF(Parameters!$E$6="","",Parameters!$E$6) -> mbar | F11: =IF(Parameters!$F$6="Check","OK / Not OK",TRIM(IF(Parameters!$I$6<>"","act <"&Parameters!$I$6&" ","")&IF(Parameters!$J$6<>"","watch <"&Parameters!$J$6&" ","")&IF(Parameters!$K$6<>"","watch >"&Parameters!$K$6&" ","")&IF(Parameters!$L$6<>"","act >"&Parameters!$L$6,""))) -> act <48 watch <53 watch >70 act >75 | G11: =IF(Parameters!$H$6="","",Parameters!$H$6) -> 60 | J11: =IF(OR(H11="",I11="",Parameters!$F$6="Check"),"",H11-I11) | K11: =IF(OR(H11="",G11="",Parameters!$F$6="Check"),"",IF(G11=0,H11-G11,(H11-G11)/ABS(G11))) | L11: =IF(LEFT(N11,2)="No","N/A",IF(H11="","",IF(Parameters!$F$6="Check",IF(H11="OK","OK","ACT"),IF(OR(AND(Parameters!$I$6<>"",H11<Parameters!$I$6),AND(Parameters!$L$6<>"",H11>Parameters!$L$6)),"ACT",IF(OR(AND(Parameters!$J$6<>"",H11<Parameters!$J$6),AND(Parameters!$K$6<>"",H11>Parameters!$K$6)),"WATCH","OK"))))) | N11: =IF(Parameters!$G$6="All","Yes",IF($C$5="","Yes",IF(ISNUMBER(SEARCH($C$5,Parameters!$G$6)),"Yes","No – N/A for "&$C$5))) -> Yes
A12: =Parameters!$A$7 -> 3 | B12: =Parameters!$B$7 -> Combustion | C12: =Parameters!$C$7 -> Combustion air blower motor current | D12: =Parameters!$D$7 -> Clamp meter or panel ammeter (% of rated current) | E12: =IF(Parameters!$E$7="","",Parameters!$E$7) -> % FLA | F12: =IF(Parameters!$F$7="Check","OK / Not OK",TRIM(IF(Parameters!$I$7<>"","act <"&Parameters!$I$7&" ","")&IF(Parameters!$J$7<>"","watch <"&Parameters!$J$7&" ","")&IF(Parameters!$K$7<>"","watch >"&Parameters!$K$7&" ","")&IF(Parameters!$L$7<>"","act >"&Parameters!$L$7,""))) -> act <40 watch <55 watch >85 act >95 | G12: =IF(Parameters!$H$7="","",Parameters!$H$7) -> 70 | J12: =IF(OR(H12="",I12="",Parameters!$F$7="Check"),"",H12-I12) | K12: =IF(OR(H12="",G12="",Parameters!$F$7="Check"),"",IF(G12=0,H12-G12,(H12-G12)/ABS(G12))) | L12: =IF(LEFT(N12,2)="No","N/A",IF(H12="","",IF(Parameters!$F$7="Check",IF(H12="OK","OK","ACT"),IF(OR(AND(Parameters!$I$7<>"",H12<Parameters!$I$7),AND(Parameters!$L$7<>"",H12>Parameters!$L$7)),"ACT",IF(OR(AND(Parameters!$J$7<>"",H12<Parameters!$J$7),AND(Parameters!$K$7<>"",H12>Parameters!$K$7)),"WATCH","OK"))))) | N12: =IF(Parameters!$G$7="All","Yes",IF($C$5="","Yes",IF(ISNUMBER(SEARCH($C$5,Parameters!$G$7)),"Yes","No – N/A for "&$C$5))) -> Yes
A13: =Parameters!$A$8 -> 4 | B13: =Parameters!$B$8 -> Combustion | C13: =Parameters!$C$8 -> Combustion air blower bearing vibration | D13: =Parameters!$D$8 -> Handheld vibration meter, velocity RMS | E13: =IF(Parameters!$E$8="","",Parameters!$E$8) -> mm/s | F13: =IF(Parameters!$F$8="Check","OK / Not OK",TRIM(IF(Parameters!$I$8<>"","act <"&Parameters!$I$8&" ","")&IF(Parameters!$J$8<>"","watch <"&Parameters!$J$8&" ","")&IF(Parameters!$K$8<>"","watch >"&Parameters!$K$8&" ","")&IF(Parameters!$L$8<>"","act >"&Parameters!$L$8,""))) -> watch >2.8 act >4.5 | G13: =IF(Parameters!$H$8="","",Parameters!$H$8) -> 1.5 | J13: =IF(OR(H13="",I13="",Parameters!$F$8="Check"),"",H13-I13) | K13: =IF(OR(H13="",G13="",Parameters!$F$8="Check"),"",IF(G13=0,H13-G13,(H13-G13)/ABS(G13))) | L13: =IF(LEFT(N13,2)="No","N/A",IF(H13="","",IF(Parameters!$F$8="Check",IF(H13="OK","OK","ACT"),IF(OR(AND(Parameters!$I$8<>"",H13<Parameters!$I$8),AND(Parameters!$L$8<>"",H13>Parameters!$L$8)),"ACT",IF(OR(AND(Parameters!$J$8<>"",H13<Parameters!$J$8),AND(Parameters!$K$8<>"",H13>Parameters!$K$8)),"WATCH","OK"))))) | N13: =IF(Parameters!$G$8="All","Yes",IF($C$5="","Yes",IF(ISNUMBER(SEARCH($C$5,Parameters!$G$8)),"Yes","No – N/A for "&$C$5))) -> Yes
A14: =Parameters!$A$9 -> 5 | B14: =Parameters!$B$9 -> Combustion | C14: =Parameters!$C$9 -> Combustion air blower bearing temperature | D14: =Parameters!$D$9 -> IR thermometer | E14: =IF(Parameters!$E$9="","",Parameters!$E$9) -> °C | F14: =IF(Parameters!$F$9="Check","OK / Not OK",TRIM(IF(Parameters!$I$9<>"","act <"&Parameters!$I$9&" ","")&IF(Parameters!$J$9<>"","watch <"&Parameters!$J$9&" ","")&IF(Parameters!$K$9<>"","watch >"&Parameters!$K$9&" ","")&IF(Parameters!$L$9<>"","act >"&Parameters!$L$9,""))) -> watch >70 act >85 | G14: =IF(Parameters!$H$9="","",Parameters!$H$9) -> 50 | J14: =IF(OR(H14="",I14="",Parameters!$F$9="Check"),"",H14-I14) | K14: =IF(OR(H14="",G14="",Parameters!$F$9="Check"),"",IF(G14=0,H14-G14,(H14-G14)/ABS(G14))) | L14: =IF(LEFT(N14,2)="No","N/A",IF(H14="","",IF(Parameters!$F$9="Check",IF(H14="OK","OK","ACT"),IF(OR(AND(Parameters!$I$9<>"",H14<Parameters!$I$9),AND(Parameters!$L$9<>"",H14>Parameters!$L$9)),"ACT",IF(OR(AND(Parameters!$J$9<>"",H14<Parameters!$J$9),AND(Parameters!$K$9<>"",H14>Parameters!$K$9)),"WATCH","OK"))))) | N14: =IF(Parameters!$G$9="All","Yes",IF($C$5="","Yes",IF(ISNUMBER(SEARCH($C$5,Parameters!$G$9)),"Yes","No – N/A for "&$C$5))) -> Yes
A15: =Parameters!$A$10 -> 6 | B15: =Parameters!$B$10 -> Combustion | C15: =Parameters!$C$10 -> Burner flame failures / lockouts in the last 24 h | D15: =Parameters!$D$10 -> Alarm log (CALOR → Alarms) / burner controller | E15: =IF(Parameters!$E$10="","",Parameters!$E$10) -> count | F15: =IF(Parameters!$F$10="Check","OK / Not OK",TRIM(IF(Parameters!$I$10<>"","act <"&Parameters!$I$10&" ","")&IF(Parameters!$J$10<>"","watch <"&Parameters!$J$10&" ","")&IF(Parameters!$K$10<>"","watch >"&Parameters!$K$10&" ","")&IF(Parameters!$L$10<>"","act >"&Parameters!$L$10,""))) -> watch >1 act >3 | G15: =IF(Parameters!$H$10="","",Parameters!$H$10) -> 0 | J15: =IF(OR(H15="",I15="",Parameters!$F$10="Check"),"",H15-I15) | K15: =IF(OR(H15="",G15="",Parameters!$F$10="Check"),"",IF(G15=0,H15-G15,(H15-G15)/ABS(G15))) | L15: =IF(LEFT(N15,2)="No","N/A",IF(H15="","",IF(Parameters!$F$10="Check",IF(H15="OK","OK","ACT"),IF(OR(AND(Parameters!$I$10<>"",H15<Parameters!$I$10),AND(Parameters!$L$10<>"",H15>Parameters!$L$10)),"ACT",IF(OR(AND(Parameters!$J$10<>"",H15<Parameters!$J$10),AND(Parameters!$K$10<>"",H15>Parameters!$K$10)),"WATCH","OK"))))) | N15: =IF(Parameters!$G$10="All","Yes",IF($C$5="","Yes",IF(ISNUMBER(SEARCH($C$5,Parameters!$G$10)),"Yes","No – N/A for "&$C$5))) -> Yes
A16: =Parameters!$A$11 -> 7 | B16: =Parameters!$B$11 -> Combustion | C16: =Parameters!$C$11 -> Highest zone controller output at steady state, hardening chamber | D16: =Parameters!$D$11 -> SCADA / controller display | E16: =IF(Parameters!$E$11="","",Parameters!$E$11) -> % | F16: =IF(Parameters!$F$11="Check","OK / Not OK",TRIM(IF(Parameters!$I$11<>"","act <"&Parameters!$I$11&" ","")&IF(Parameters!$J$11<>"","watch <"&Parameters!$J$11&" ","")&IF(Parameters!$K$11<>"","watch >"&Parameters!$K$11&" ","")&IF(Parameters!$L$11<>"","act >"&Parameters!$L$11,""))) -> watch >75 act >90 | G16: =IF(Parameters!$H$11="","",Parameters!$H$11) -> 55 | J16: =IF(OR(H16="",I16="",Parameters!$F$11="Check"),"",H16-I16) | K16: =IF(OR(H16="",G16="",Parameters!$F$11="Check"),"",IF(G16=0,H16-G16,(H16-G16)/ABS(G16))) | L16: =IF(LEFT(N16,2)="No","N/A",IF(H16="","",IF(Parameters!$F$11="Check",IF(H16="OK","OK","ACT"),IF(OR(AND(Parameters!$I$11<>"",H16<Parameters!$I$11),AND(Parameters!$L$11<>"",H16>Parameters!$L$11)),"ACT",IF(OR(AND(Parameters!$J$11<>"",H16<Parameters!$J$11),AND(Parameters!$K$11<>"",H16>Parameters!$K$11)),"WATCH","OK"))))) | N16: =IF(Parameters!$G$11="All","Yes",IF($C$5="","Yes",IF(ISNUMBER(SEARCH($C$5,Parameters!$G$11)),"Yes","No – N/A for "&$C$5))) -> Yes
A17: =Parameters!$A$12 -> 8 | B17: =Parameters!$B$12 -> Combustion | C17: =Parameters!$C$12 -> Highest zone controller output at steady state, tempering chamber | D17: =Parameters!$D$12 -> SCADA / controller display | E17: =IF(Parameters!$E$12="","",Parameters!$E$12) -> % | F17: =IF(Parameters!$F$12="Check","OK / Not OK",TRIM(IF(Parameters!$I$12<>"","act <"&Parameters!$I$12&" ","")&IF(Parameters!$J$12<>"","watch <"&Parameters!$J$12&" ","")&IF(Parameters!$K$12<>"","watch >"&Parameters!$K$12&" ","")&IF(Parameters!$L$12<>"","act >"&Parameters!$L$12,""))) -> watch >70 act >85 | G17: =IF(Parameters!$H$12="","",Parameters!$H$12) -> 45 | J17: =IF(OR(H17="",I17="",Parameters!$F$12="Check"),"",H17-I17) | K17: =IF(OR(H17="",G17="",Parameters!$F$12="Check"),"",IF(G17=0,H17-G17,(H17-G17)/ABS(G17))) | L17: =IF(LEFT(N17,2)="No","N/A",IF(H17="","",IF(Parameters!$F$12="Check",IF(H17="OK","OK","ACT"),IF(OR(AND(Parameters!$I$12<>"",H17<Parameters!$I$12),AND(Parameters!$L$12<>"",H17>Parameters!$L$12)),"ACT",IF(OR(AND(Parameters!$J$12<>"",H17<Parameters!$J$12),AND(Parameters!$K$12<>"",H17>Parameters!$K$12)),"WATCH","OK"))))) | N17: =IF(Parameters!$G$12="All","Yes",IF($C$5="","Yes",IF(ISNUMBER(SEARCH($C$5,Parameters!$G$12)),"Yes","No – N/A for "&$C$5))) -> Yes
A18: =Parameters!$A$13 -> 9 | B18: =Parameters!$B$13 -> Temperature | C18: =Parameters!$C$13 -> Largest wall difference (left − right) of a zone, hardening chamber | D18: =Parameters!$D$13 -> SCADA (TC odd = right, even = left) | E18: =IF(Parameters!$E$13="","",Parameters!$E$13) -> °C | F18: =IF(Parameters!$F$13="Check","OK / Not OK",TRIM(IF(Parameters!$I$13<>"","act <"&Parameters!$I$13&" ","")&IF(Parameters!$J$13<>"","watch <"&Parameters!$J$13&" ","")&IF(Parameters!$K$13<>"","watch >"&Parameters!$K$13&" ","")&IF(Parameters!$L$13<>"","act >"&Parameters!$L$13,""))) -> act <-8 watch <-5 watch >5 act >8 | G18: =IF(Parameters!$H$13="","",Parameters!$H$13) -> 0 | J18: =IF(OR(H18="",I18="",Parameters!$F$13="Check"),"",H18-I18) | K18: =IF(OR(H18="",G18="",Parameters!$F$13="Check"),"",IF(G18=0,H18-G18,(H18-G18)/ABS(G18))) | L18: =IF(LEFT(N18,2)="No","N/A",IF(H18="","",IF(Parameters!$F$13="Check",IF(H18="OK","OK","ACT"),IF(OR(AND(Parameters!$I$13<>"",H18<Parameters!$I$13),AND(Parameters!$L$13<>"",H18>Parameters!$L$13)),"ACT",IF(OR(AND(Parameters!$J$13<>"",H18<Parameters!$J$13),AND(Parameters!$K$13<>"",H18>Parameters!$K$13)),"WATCH","OK"))))) | N18: =IF(Parameters!$G$13="All","Yes",IF($C$5="","Yes",IF(ISNUMBER(SEARCH($C$5,Parameters!$G$13)),"Yes","No – N/A for "&$C$5))) -> Yes
A19: =Parameters!$A$14 -> 10 | B19: =Parameters!$B$14 -> Temperature | C19: =Parameters!$C$14 -> Largest wall difference (left − right) of a zone, tempering chamber | D19: =Parameters!$D$14 -> SCADA (TC odd = right, even = left) | E19: =IF(Parameters!$E$14="","",Parameters!$E$14) -> °C | F19: =IF(Parameters!$F$14="Check","OK / Not OK",TRIM(IF(Parameters!$I$14<>"","act <"&Parameters!$I$14&" ","")&IF(Parameters!$J$14<>"","watch <"&Parameters!$J$14&" ","")&IF(Parameters!$K$14<>"","watch >"&Parameters!$K$14&" ","")&IF(Parameters!$L$14<>"","act >"&Parameters!$L$14,""))) -> act <-8 watch <-5 watch >5 act >8 | G19: =IF(Parameters!$H$14="","",Parameters!$H$14) -> 0 | J19: =IF(OR(H19="",I19="",Parameters!$F$14="Check"),"",H19-I19) | K19: =IF(OR(H19="",G19="",Parameters!$F$14="Check"),"",IF(G19=0,H19-G19,(H19-G19)/ABS(G19))) | L19: =IF(LEFT(N19,2)="No","N/A",IF(H19="","",IF(Parameters!$F$14="Check",IF(H19="OK","OK","ACT"),IF(OR(AND(Parameters!$I$14<>"",H19<Parameters!$I$14),AND(Parameters!$L$14<>"",H19>Parameters!$L$14)),"ACT",IF(OR(AND(Parameters!$J$14<>"",H19<Parameters!$J$14),AND(Parameters!$K$14<>"",H19>Parameters!$K$14)),"WATCH","OK"))))) | N19: =IF(Parameters!$G$14="All","Yes",IF($C$5="","Yes",IF(ISNUMBER(SEARCH($C$5,Parameters!$G$14)),"Yes","No – N/A for "&$C$5))) -> Yes
A20: =Parameters!$A$15 -> 11 | B20: =Parameters!$B$15 -> Temperature | C20: =Parameters!$C$15 -> Over-temperature controller reading vs control thermocouple (difference) | D20: =Parameters!$D$15 -> Panel displays | E20: =IF(Parameters!$E$15="","",Parameters!$E$15) -> °C | F20: =IF(Parameters!$F$15="Check","OK / Not OK",TRIM(IF(Parameters!$I$15<>"","act <"&Parameters!$I$15&" ","")&IF(Parameters!$J$15<>"","watch <"&Parameters!$J$15&" ","")&IF(Parameters!$K$15<>"","watch >"&Parameters!$K$15&" ","")&IF(Parameters!$L$15<>"","act >"&Parameters!$L$15,""))) -> act <-8 watch <-5 watch >5 act >8 | G20: =IF(Parameters!$H$15="","",Parameters!$H$15) -> 0 | J20: =IF(OR(H20="",I20="",Parameters!$F$15="Check"),"",H20-I20) | K20: =IF(OR(H20="",G20="",Parameters!$F$15="Check"),"",IF(G20=0,H20-G20,(H20-G20)/ABS(G20))) | L20: =IF(LEFT(N20,2)="No","N/A",IF(H20="","",IF(Parameters!$F$15="Check",IF(H20="OK","OK","ACT"),IF(OR(AND(Parameters!$I$15<>"",H20<Parameters!$I$15),AND(Parameters!$L$15<>"",H20>Parameters!$L$15)),"ACT",IF(OR(AND(Parameters!$J$15<>"",H20<Parameters!$J$15),AND(Parameters!$K$15<>"",H20>Parameters!$K$15)),"WATCH","OK"))))) | N20: =IF(Parameters!$G$15="All","Yes",IF($C$5="","Yes",IF(ISNUMBER(SEARCH($C$5,Parameters!$G$15)),"Yes","No – N/A for "&$C$5))) -> Yes
A21: =Parameters!$A$16 -> 12 | B21: =Parameters!$B$16 -> Refractory | C21: =Parameters!$C$16 -> Furnace shell hottest spot (IR scan of walls, roof, doors) | D21: =Parameters!$D$16 -> IR thermometer / camera, same route daily | E21: =IF(Parameters!$E$16="","",Parameters!$E$16) -> °C | F21: =IF(Parameters!$F$16="Check","OK / Not OK",TRIM(IF(Parameters!$I$16<>"","act <"&Parameters!$I$16&" ","")&IF(Parameters!$J$16<>"","watch <"&Parameters!$J$16&" ","")&IF(Parameters!$K$16<>"","watch >"&Parameters!$K$16&" ","")&IF(Parameters!$L$16<>"","act >"&Parameters!$L$16,""))) -> watch >100 act >120 | G21: =IF(Parameters!$H$16="","",Parameters!$H$16) -> 70 | J21: =IF(OR(H21="",I21="",Parameters!$F$16="Check"),"",H21-I21) | K21: =IF(OR(H21="",G21="",Parameters!$F$16="Check"),"",IF(G21=0,H21-G21,(H21-G21)/ABS(G21))) | L21: =IF(LEFT(N21,2)="No","N/A",IF(H21="","",IF(Parameters!$F$16="Check",IF(H21="OK","OK","ACT"),IF(OR(AND(Parameters!$I$16<>"",H21<Parameters!$I$16),AND(Parameters!$L$16<>"",H21>Parameters!$L$16)),"ACT",IF(OR(AND(Parameters!$J$16<>"",H21<Parameters!$J$16),AND(Parameters!$K$16<>"",H21>Parameters!$K$16)),"WATCH","OK"))))) | N21: =IF(Parameters!$G$16="All","Yes",IF($C$5="","Yes",IF(ISNUMBER(SEARCH($C$5,Parameters!$G$16)),"Yes","No – N/A for "&$C$5))) -> Yes
A22: =Parameters!$A$17 -> 13 | B22: =Parameters!$B$17 -> Refractory | C22: =Parameters!$C$17 -> Door seals and flame curtains intact, no flame out of doors | D22: =Parameters!$D$17 -> Visual | E22: =IF(Parameters!$E$17="","",Parameters!$E$17) | F22: =IF(Parameters!$F$17="Check","OK / Not OK",TRIM(IF(Parameters!$I$17<>"","act <"&Parameters!$I$17&" ","")&IF(Parameters!$J$17<>"","watch <"&Parameters!$J$17&" ","")&IF(Parameters!$K$17<>"","watch >"&Parameters!$K$17&" ","")&IF(Parameters!$L$17<>"","act >"&Parameters!$L$17,""))) -> OK / Not OK | G22: =IF(Parameters!$H$17="","",Parameters!$H$17) | J22: =IF(OR(H22="",I22="",Parameters!$F$17="Check"),"",H22-I22) | K22: =IF(OR(H22="",G22="",Parameters!$F$17="Check"),"",IF(G22=0,H22-G22,(H22-G22)/ABS(G22))) | L22: =IF(LEFT(N22,2)="No","N/A",IF(H22="","",IF(Parameters!$F$17="Check",IF(H22="OK","OK","ACT"),IF(OR(AND(Parameters!$I$17<>"",H22<Parameters!$I$17),AND(Parameters!$L$17<>"",H22>Parameters!$L$17)),"ACT",IF(OR(AND(Parameters!$J$17<>"",H22<Parameters!$J$17),AND(Parameters!$K$17<>"",H22>Parameters!$K$17)),"WATCH","OK"))))) | N22: =IF(Parameters!$G$17="All","Yes",IF($C$5="","Yes",IF(ISNUMBER(SEARCH($C$5,Parameters!$G$17)),"Yes","No – N/A for "&$C$5))) -> Yes
A23: =Parameters!$A$18 -> 14 | B23: =Parameters!$B$18 -> Pusher | C23: =Parameters!$C$18 -> Pusher hydraulic pressure during the push | D23: =Parameters!$D$18 -> Hydraulic gauge at mid-stroke | E23: =IF(Parameters!$E$18="","",Parameters!$E$18) -> bar | F23: =IF(Parameters!$F$18="Check","OK / Not OK",TRIM(IF(Parameters!$I$18<>"","act <"&Parameters!$I$18&" ","")&IF(Parameters!$J$18<>"","watch <"&Parameters!$J$18&" ","")&IF(Parameters!$K$18<>"","watch >"&Parameters!$K$18&" ","")&IF(Parameters!$L$18<>"","act >"&Parameters!$L$18,""))) -> watch >110 act >130 | G23: =IF(Parameters!$H$18="","",Parameters!$H$18) -> 80 | J23: =IF(OR(H23="",I23="",Parameters!$F$18="Check"),"",H23-I23) | K23: =IF(OR(H23="",G23="",Parameters!$F$18="Check"),"",IF(G23=0,H23-G23,(H23-G23)/ABS(G23))) | L23: =IF(LEFT(N23,2)="No","N/A",IF(H23="","",IF(Parameters!$F$18="Check",IF(H23="OK","OK","ACT"),IF(OR(AND(Parameters!$I$18<>"",H23<Parameters!$I$18),AND(Parameters!$L$18<>"",H23>Parameters!$L$18)),"ACT",IF(OR(AND(Parameters!$J$18<>"",H23<Parameters!$J$18),AND(Parameters!$K$18<>"",H23>Parameters!$K$18)),"WATCH","OK"))))) | N23: =IF(Parameters!$G$18="All","Yes",IF($C$5="","Yes",IF(ISNUMBER(SEARCH($C$5,Parameters!$G$18)),"Yes","No – N/A for "&$C$5))) -> Yes
A24: =Parameters!$A$19 -> 15 | B24: =Parameters!$B$19 -> Pusher | C24: =Parameters!$C$19 -> Push stroke time (one full push) | D24: =Parameters!$D$19 -> Stopwatch / PLC | E24: =IF(Parameters!$E$19="","",Parameters!$E$19) -> s | F24: =IF(Parameters!$F$19="Check","OK / Not OK",TRIM(IF(Parameters!$I$19<>"","act <"&Parameters!$I$19&" ","")&IF(Parameters!$J$19<>"","watch <"&Parameters!$J$19&" ","")&IF(Parameters!$K$19<>"","watch >"&Parameters!$K$19&" ","")&IF(Parameters!$L$19<>"","act >"&Parameters!$L$19,""))) -> watch >36 act >40 | G24: =IF(Parameters!$H$19="","",Parameters!$H$19) -> 30 | J24: =IF(OR(H24="",I24="",Parameters!$F$19="Check"),"",H24-I24) | K24: =IF(OR(H24="",G24="",Parameters!$F$19="Check"),"",IF(G24=0,H24-G24,(H24-G24)/ABS(G24))) | L24: =IF(LEFT(N24,2)="No","N/A",IF(H24="","",IF(Parameters!$F$19="Check",IF(H24="OK","OK","ACT"),IF(OR(AND(Parameters!$I$19<>"",H24<Parameters!$I$19),AND(Parameters!$L$19<>"",H24>Parameters!$L$19)),"ACT",IF(OR(AND(Parameters!$J$19<>"",H24<Parameters!$J$19),AND(Parameters!$K$19<>"",H24>Parameters!$K$19)),"WATCH","OK"))))) | N24: =IF(Parameters!$G$19="All","Yes",IF($C$5="","Yes",IF(ISNUMBER(SEARCH($C$5,Parameters!$G$19)),"Yes","No – N/A for "&$C$5))) -> Yes
A25: =Parameters!$A$20 -> 16 | B25: =Parameters!$B$20 -> Pusher | C25: =Parameters!$C$20 -> Hydraulic oil temperature | D25: =Parameters!$D$20 -> Tank thermometer | E25: =IF(Parameters!$E$20="","",Parameters!$E$20) -> °C | F25: =IF(Parameters!$F$20="Check","OK / Not OK",TRIM(IF(Parameters!$I$20<>"","act <"&Parameters!$I$20&" ","")&IF(Parameters!$J$20<>"","watch <"&Parameters!$J$20&" ","")&IF(Parameters!$K$20<>"","watch >"&Parameters!$K$20&" ","")&IF(Parameters!$L$20<>"","act >"&Parameters!$L$20,""))) -> watch >55 act >60 | G25: =IF(Parameters!$H$20="","",Parameters!$H$20) -> 45 | J25: =IF(OR(H25="",I25="",Parameters!$F$20="Check"),"",H25-I25) | K25: =IF(OR(H25="",G25="",Parameters!$F$20="Check"),"",IF(G25=0,H25-G25,(H25-G25)/ABS(G25))) | L25: =IF(LEFT(N25,2)="No","N/A",IF(H25="","",IF(Parameters!$F$20="Check",IF(H25="OK","OK","ACT"),IF(OR(AND(Parameters!$I$20<>"",H25<Parameters!$I$20),AND(Parameters!$L$20<>"",H25>Parameters!$L$20)),"ACT",IF(OR(AND(Parameters!$J$20<>"",H25<Parameters!$J$20),AND(Parameters!$K$20<>"",H25>Parameters!$K$20)),"WATCH","OK"))))) | N25: =IF(Parameters!$G$20="All","Yes",IF($C$5="","Yes",IF(ISNUMBER(SEARCH($C$5,Parameters!$G$20)),"Yes","No – N/A for "&$C$5))) -> Yes
A26: =Parameters!$A$21 -> 17 | B26: =Parameters!$B$21 -> Pusher | C26: =Parameters!$C$21 -> Hydraulic oil level and no leaks | D26: =Parameters!$D$21 -> Sight glass / visual | E26: =IF(Parameters!$E$21="","",Parameters!$E$21) | F26: =IF(Parameters!$F$21="Check","OK / Not OK",TRIM(IF(Parameters!$I$21<>"","act <"&Parameters!$I$21&" ","")&IF(Parameters!$J$21<>"","watch <"&Parameters!$J$21&" ","")&IF(Parameters!$K$21<>"","watch >"&Parameters!$K$21&" ","")&IF(Parameters!$L$21<>"","act >"&Parameters!$L$21,""))) -> OK / Not OK | G26: =IF(Parameters!$H$21="","",Parameters!$H$21) | J26: =IF(OR(H26="",I26="",Parameters!$F$21="Check"),"",H26-I26) | K26: =IF(OR(H26="",G26="",Parameters!$F$21="Check"),"",IF(G26=0,H26-G26,(H26-G26)/ABS(G26))) | L26: =IF(LEFT(N26,2)="No","N/A",IF(H26="","",IF(Parameters!$F$21="Check",IF(H26="OK","OK","ACT"),IF(OR(AND(Parameters!$I$21<>"",H26<Parameters!$I$21),AND(Parameters!$L$21<>"",H26>Parameters!$L$21)),"ACT",IF(OR(AND(Parameters!$J$21<>"",H26<Parameters!$J$21),AND(Parameters!$K$21<>"",H26>Parameters!$K$21)),"WATCH","OK"))))) | N26: =IF(Parameters!$G$21="All","Yes",IF($C$5="","Yes",IF(ISNUMBER(SEARCH($C$5,Parameters!$G$21)),"Yes","No – N/A for "&$C$5))) -> Yes
A27: =Parameters!$A$22 -> 18 | B27: =Parameters!$B$22 -> Transfer | C27: =Parameters!$C$22 -> Extractor / rail transfer drive motor current | D27: =Parameters!$D$22 -> Clamp meter or panel ammeter (% of rated) | E27: =IF(Parameters!$E$22="","",Parameters!$E$22) -> % FLA | F27: =IF(Parameters!$F$22="Check","OK / Not OK",TRIM(IF(Parameters!$I$22<>"","act <"&Parameters!$I$22&" ","")&IF(Parameters!$J$22<>"","watch <"&Parameters!$J$22&" ","")&IF(Parameters!$K$22<>"","watch >"&Parameters!$K$22&" ","")&IF(Parameters!$L$22<>"","act >"&Parameters!$L$22,""))) -> watch >80 act >90 | G27: =IF(Parameters!$H$22="","",Parameters!$H$22) -> 60 | J27: =IF(OR(H27="",I27="",Parameters!$F$22="Check"),"",H27-I27) | K27: =IF(OR(H27="",G27="",Parameters!$F$22="Check"),"",IF(G27=0,H27-G27,(H27-G27)/ABS(G27))) | L27: =IF(LEFT(N27,2)="No","N/A",IF(H27="","",IF(Parameters!$F$22="Check",IF(H27="OK","OK","ACT"),IF(OR(AND(Parameters!$I$22<>"",H27<Parameters!$I$22),AND(Parameters!$L$22<>"",H27>Parameters!$L$22)),"ACT",IF(OR(AND(Parameters!$J$22<>"",H27<Parameters!$J$22),AND(Parameters!$K$22<>"",H27>Parameters!$K$22)),"WATCH","OK"))))) | N27: =IF(Parameters!$G$22="All","Yes",IF($C$5="","Yes",IF(ISNUMBER(SEARCH($C$5,Parameters!$G$22)),"Yes","No – N/A for "&$C$5))) -> Yes
A28: =Parameters!$A$23 -> 19 | B28: =Parameters!$B$23 -> Transfer | C28: =Parameters!$C$23 -> Chains, rails and rollers: lubricated, no abnormal noise | D28: =Parameters!$D$23 -> Visual / listen | E28: =IF(Parameters!$E$23="","",Parameters!$E$23) | F28: =IF(Parameters!$F$23="Check","OK / Not OK",TRIM(IF(Parameters!$I$23<>"","act <"&Parameters!$I$23&" ","")&IF(Parameters!$J$23<>"","watch <"&Parameters!$J$23&" ","")&IF(Parameters!$K$23<>"","watch >"&Parameters!$K$23&" ","")&IF(Parameters!$L$23<>"","act >"&Parameters!$L$23,""))) -> OK / Not OK | G28: =IF(Parameters!$H$23="","",Parameters!$H$23) | J28: =IF(OR(H28="",I28="",Parameters!$F$23="Check"),"",H28-I28) | K28: =IF(OR(H28="",G28="",Parameters!$F$23="Check"),"",IF(G28=0,H28-G28,(H28-G28)/ABS(G28))) | L28: =IF(LEFT(N28,2)="No","N/A",IF(H28="","",IF(Parameters!$F$23="Check",IF(H28="OK","OK","ACT"),IF(OR(AND(Parameters!$I$23<>"",H28<Parameters!$I$23),AND(Parameters!$L$23<>"",H28>Parameters!$L$23)),"ACT",IF(OR(AND(Parameters!$J$23<>"",H28<Parameters!$J$23),AND(Parameters!$K$23<>"",H28>Parameters!$K$23)),"WATCH","OK"))))) | N28: =IF(Parameters!$G$23="All","Yes",IF($C$5="","Yes",IF(ISNUMBER(SEARCH($C$5,Parameters!$G$23)),"Yes","No – N/A for "&$C$5))) -> Yes
A29: =Parameters!$A$24 -> 20 | B29: =Parameters!$B$24 -> Controlled cooling | C29: =Parameters!$C$24 -> Cooling chamber blower motor current | D29: =Parameters!$D$24 -> Clamp meter or panel ammeter (% of rated) | E29: =IF(Parameters!$E$24="","",Parameters!$E$24) -> % FLA | F29: =IF(Parameters!$F$24="Check","OK / Not OK",TRIM(IF(Parameters!$I$24<>"","act <"&Parameters!$I$24&" ","")&IF(Parameters!$J$24<>"","watch <"&Parameters!$J$24&" ","")&IF(Parameters!$K$24<>"","watch >"&Parameters!$K$24&" ","")&IF(Parameters!$L$24<>"","act >"&Parameters!$L$24,""))) -> act <45 watch <55 watch >85 act >95 | G29: =IF(Parameters!$H$24="","",Parameters!$H$24) -> 70 | J29: =IF(OR(H29="",I29="",Parameters!$F$24="Check"),"",H29-I29) | K29: =IF(OR(H29="",G29="",Parameters!$F$24="Check"),"",IF(G29=0,H29-G29,(H29-G29)/ABS(G29))) | L29: =IF(LEFT(N29,2)="No","N/A",IF(H29="","",IF(Parameters!$F$24="Check",IF(H29="OK","OK","ACT"),IF(OR(AND(Parameters!$I$24<>"",H29<Parameters!$I$24),AND(Parameters!$L$24<>"",H29>Parameters!$L$24)),"ACT",IF(OR(AND(Parameters!$J$24<>"",H29<Parameters!$J$24),AND(Parameters!$K$24<>"",H29>Parameters!$K$24)),"WATCH","OK"))))) | N29: =IF(Parameters!$G$24="All","Yes",IF($C$5="","Yes",IF(ISNUMBER(SEARCH($C$5,Parameters!$G$24)),"Yes","No – N/A for "&$C$5))) -> Yes
A30: =Parameters!$A$25 -> 21 | B30: =Parameters!$B$25 -> Controlled cooling | C30: =Parameters!$C$25 -> Cooling chamber blower bearing vibration | D30: =Parameters!$D$25 -> Handheld vibration meter, velocity RMS | E30: =IF(Parameters!$E$25="","",Parameters!$E$25) -> mm/s | F30: =IF(Parameters!$F$25="Check","OK / Not OK",TRIM(IF(Parameters!$I$25<>"","act <"&Parameters!$I$25&" ","")&IF(Parameters!$J$25<>"","watch <"&Parameters!$J$25&" ","")&IF(Parameters!$K$25<>"","watch >"&Parameters!$K$25&" ","")&IF(Parameters!$L$25<>"","act >"&Parameters!$L$25,""))) -> watch >2.8 act >4.5 | G30: =IF(Parameters!$H$25="","",Parameters!$H$25) -> 1.5 | J30: =IF(OR(H30="",I30="",Parameters!$F$25="Check"),"",H30-I30) | K30: =IF(OR(H30="",G30="",Parameters!$F$25="Check"),"",IF(G30=0,H30-G30,(H30-G30)/ABS(G30))) | L30: =IF(LEFT(N30,2)="No","N/A",IF(H30="","",IF(Parameters!$F$25="Check",IF(H30="OK","OK","ACT"),IF(OR(AND(Parameters!$I$25<>"",H30<Parameters!$I$25),AND(Parameters!$L$25<>"",H30>Parameters!$L$25)),"ACT",IF(OR(AND(Parameters!$J$25<>"",H30<Parameters!$J$25),AND(Parameters!$K$25<>"",H30>Parameters!$K$25)),"WATCH","OK"))))) | N30: =IF(Parameters!$G$25="All","Yes",IF($C$5="","Yes",IF(ISNUMBER(SEARCH($C$5,Parameters!$G$25)),"Yes","No – N/A for "&$C$5))) -> Yes
A31: =Parameters!$A$26 -> 22 | B31: =Parameters!$B$26 -> Quench | C31: =Parameters!$C$26 -> Water quench tank temperature at the start of the shift | D31: =Parameters!$D$26 -> Tank indicator / thermometer | E31: =IF(Parameters!$E$26="","",Parameters!$E$26) -> °C | F31: =IF(Parameters!$F$26="Check","OK / Not OK",TRIM(IF(Parameters!$I$26<>"","act <"&Parameters!$I$26&" ","")&IF(Parameters!$J$26<>"","watch <"&Parameters!$J$26&" ","")&IF(Parameters!$K$26<>"","watch >"&Parameters!$K$26&" ","")&IF(Parameters!$L$26<>"","act >"&Parameters!$L$26,""))) -> watch >32 act >35 | G31: =IF(Parameters!$H$26="","",Parameters!$H$26) -> 28 | J31: =IF(OR(H31="",I31="",Parameters!$F$26="Check"),"",H31-I31) | K31: =IF(OR(H31="",G31="",Parameters!$F$26="Check"),"",IF(G31=0,H31-G31,(H31-G31)/ABS(G31))) | L31: =IF(LEFT(N31,2)="No","N/A",IF(H31="","",IF(Parameters!$F$26="Check",IF(H31="OK","OK","ACT"),IF(OR(AND(Parameters!$I$26<>"",H31<Parameters!$I$26),AND(Parameters!$L$26<>"",H31>Parameters!$L$26)),"ACT",IF(OR(AND(Parameters!$J$26<>"",H31<Parameters!$J$26),AND(Parameters!$K$26<>"",H31>Parameters!$K$26)),"WATCH","OK"))))) | N31: =IF(Parameters!$G$26="All","Yes",IF($C$5="","Yes",IF(ISNUMBER(SEARCH($C$5,Parameters!$G$26)),"Yes","No – N/A for "&$C$5))) -> Yes
A32: =Parameters!$A$27 -> 23 | B32: =Parameters!$B$27 -> Quench | C32: =Parameters!$C$27 -> Oil quench tank temperature at the start of the shift | D32: =Parameters!$D$27 -> Tank indicator / thermometer | E32: =IF(Parameters!$E$27="","",Parameters!$E$27) -> °C | F32: =IF(Parameters!$F$27="Check","OK / Not OK",TRIM(IF(Parameters!$I$27<>"","act <"&Parameters!$I$27&" ","")&IF(Parameters!$J$27<>"","watch <"&Parameters!$J$27&" ","")&IF(Parameters!$K$27<>"","watch >"&Parameters!$K$27&" ","")&IF(Parameters!$L$27<>"","act >"&Parameters!$L$27,""))) -> act <50 watch <54 watch >76 act >80 | G32: =IF(Parameters!$H$27="","",Parameters!$H$27) -> 62 | J32: =IF(OR(H32="",I32="",Parameters!$F$27="Check"),"",H32-I32) | K32: =IF(OR(H32="",G32="",Parameters!$F$27="Check"),"",IF(G32=0,H32-G32,(H32-G32)/ABS(G32))) | L32: =IF(LEFT(N32,2)="No","N/A",IF(H32="","",IF(Parameters!$F$27="Check",IF(H32="OK","OK","ACT"),IF(OR(AND(Parameters!$I$27<>"",H32<Parameters!$I$27),AND(Parameters!$L$27<>"",H32>Parameters!$L$27)),"ACT",IF(OR(AND(Parameters!$J$27<>"",H32<Parameters!$J$27),AND(Parameters!$K$27<>"",H32>Parameters!$K$27)),"WATCH","OK"))))) | N32: =IF(Parameters!$G$27="All","Yes",IF($C$5="","Yes",IF(ISNUMBER(SEARCH($C$5,Parameters!$G$27)),"Yes","No – N/A for "&$C$5))) -> Yes
A33: =Parameters!$A$28 -> 24 | B33: =Parameters!$B$28 -> Quench | C33: =Parameters!$C$28 -> Quench agitator motor current (agitation is not monitored: current is the indicator) | D33: =Parameters!$D$28 -> Clamp meter or panel ammeter (% of rated) | E33: =IF(Parameters!$E$28="","",Parameters!$E$28) -> % FLA | F33: =IF(Parameters!$F$28="Check","OK / Not OK",TRIM(IF(Parameters!$I$28<>"","act <"&Parameters!$I$28&" ","")&IF(Parameters!$J$28<>"","watch <"&Parameters!$J$28&" ","")&IF(Parameters!$K$28<>"","watch >"&Parameters!$K$28&" ","")&IF(Parameters!$L$28<>"","act >"&Parameters!$L$28,""))) -> act <45 watch <55 watch >90 act >100 | G33: =IF(Parameters!$H$28="","",Parameters!$H$28) -> 70 | J33: =IF(OR(H33="",I33="",Parameters!$F$28="Check"),"",H33-I33) | K33: =IF(OR(H33="",G33="",Parameters!$F$28="Check"),"",IF(G33=0,H33-G33,(H33-G33)/ABS(G33))) | L33: =IF(LEFT(N33,2)="No","N/A",IF(H33="","",IF(Parameters!$F$28="Check",IF(H33="OK","OK","ACT"),IF(OR(AND(Parameters!$I$28<>"",H33<Parameters!$I$28),AND(Parameters!$L$28<>"",H33>Parameters!$L$28)),"ACT",IF(OR(AND(Parameters!$J$28<>"",H33<Parameters!$J$28),AND(Parameters!$K$28<>"",H33>Parameters!$K$28)),"WATCH","OK"))))) | N33: =IF(Parameters!$G$28="All","Yes",IF($C$5="","Yes",IF(ISNUMBER(SEARCH($C$5,Parameters!$G$28)),"Yes","No – N/A for "&$C$5))) -> Yes
A34: =Parameters!$A$29 -> 25 | B34: =Parameters!$B$29 -> Quench | C34: =Parameters!$C$29 -> Oil cooler temperature drop (oil in − oil out) | D34: =Parameters!$D$29 -> Thermometers at the cooler | E34: =IF(Parameters!$E$29="","",Parameters!$E$29) -> °C | F34: =IF(Parameters!$F$29="Check","OK / Not OK",TRIM(IF(Parameters!$I$29<>"","act <"&Parameters!$I$29&" ","")&IF(Parameters!$J$29<>"","watch <"&Parameters!$J$29&" ","")&IF(Parameters!$K$29<>"","watch >"&Parameters!$K$29&" ","")&IF(Parameters!$L$29<>"","act >"&Parameters!$L$29,""))) -> act <3 watch <5 | G34: =IF(Parameters!$H$29="","",Parameters!$H$29) -> 8 | J34: =IF(OR(H34="",I34="",Parameters!$F$29="Check"),"",H34-I34) | K34: =IF(OR(H34="",G34="",Parameters!$F$29="Check"),"",IF(G34=0,H34-G34,(H34-G34)/ABS(G34))) | L34: =IF(LEFT(N34,2)="No","N/A",IF(H34="","",IF(Parameters!$F$29="Check",IF(H34="OK","OK","ACT"),IF(OR(AND(Parameters!$I$29<>"",H34<Parameters!$I$29),AND(Parameters!$L$29<>"",H34>Parameters!$L$29)),"ACT",IF(OR(AND(Parameters!$J$29<>"",H34<Parameters!$J$29),AND(Parameters!$K$29<>"",H34>Parameters!$K$29)),"WATCH","OK"))))) | N34: =IF(Parameters!$G$29="All","Yes",IF($C$5="","Yes",IF(ISNUMBER(SEARCH($C$5,Parameters!$G$29)),"Yes","No – N/A for "&$C$5))) -> Yes
A35: =Parameters!$A$30 -> 26 | B35: =Parameters!$B$30 -> Quench | C35: =Parameters!$C$30 -> Quench elevator / conveyor: no abnormal noise, chain tension | D35: =Parameters!$D$30 -> Visual / listen | E35: =IF(Parameters!$E$30="","",Parameters!$E$30) | F35: =IF(Parameters!$F$30="Check","OK / Not OK",TRIM(IF(Parameters!$I$30<>"","act <"&Parameters!$I$30&" ","")&IF(Parameters!$J$30<>"","watch <"&Parameters!$J$30&" ","")&IF(Parameters!$K$30<>"","watch >"&Parameters!$K$30&" ","")&IF(Parameters!$L$30<>"","act >"&Parameters!$L$30,""))) -> OK / Not OK | G35: =IF(Parameters!$H$30="","",Parameters!$H$30) | J35: =IF(OR(H35="",I35="",Parameters!$F$30="Check"),"",H35-I35) | K35: =IF(OR(H35="",G35="",Parameters!$F$30="Check"),"",IF(G35=0,H35-G35,(H35-G35)/ABS(G35))) | L35: =IF(LEFT(N35,2)="No","N/A",IF(H35="","",IF(Parameters!$F$30="Check",IF(H35="OK","OK","ACT"),IF(OR(AND(Parameters!$I$30<>"",H35<Parameters!$I$30),AND(Parameters!$L$30<>"",H35>Parameters!$L$30)),"ACT",IF(OR(AND(Parameters!$J$30<>"",H35<Parameters!$J$30),AND(Parameters!$K$30<>"",H35>Parameters!$K$30)),"WATCH","OK"))))) | N35: =IF(Parameters!$G$30="All","Yes",IF($C$5="","Yes",IF(ISNUMBER(SEARCH($C$5,Parameters!$G$30)),"Yes","No – N/A for "&$C$5))) -> Yes
A36: =Parameters!$A$31 -> 27 | B36: =Parameters!$B$31 -> Electrical | C36: =Parameters!$C$31 -> Control panel internal temperature | D36: =Parameters!$D$31 -> Panel thermometer / IR | E36: =IF(Parameters!$E$31="","",Parameters!$E$31) -> °C | F36: =IF(Parameters!$F$31="Check","OK / Not OK",TRIM(IF(Parameters!$I$31<>"","act <"&Parameters!$I$31&" ","")&IF(Parameters!$J$31<>"","watch <"&Parameters!$J$31&" ","")&IF(Parameters!$K$31<>"","watch >"&Parameters!$K$31&" ","")&IF(Parameters!$L$31<>"","act >"&Parameters!$L$31,""))) -> watch >40 act >45 | G36: =IF(Parameters!$H$31="","",Parameters!$H$31) -> 35 | J36: =IF(OR(H36="",I36="",Parameters!$F$31="Check"),"",H36-I36) | K36: =IF(OR(H36="",G36="",Parameters!$F$31="Check"),"",IF(G36=0,H36-G36,(H36-G36)/ABS(G36))) | L36: =IF(LEFT(N36,2)="No","N/A",IF(H36="","",IF(Parameters!$F$31="Check",IF(H36="OK","OK","ACT"),IF(OR(AND(Parameters!$I$31<>"",H36<Parameters!$I$31),AND(Parameters!$L$31<>"",H36>Parameters!$L$31)),"ACT",IF(OR(AND(Parameters!$J$31<>"",H36<Parameters!$J$31),AND(Parameters!$K$31<>"",H36>Parameters!$K$31)),"WATCH","OK"))))) | N36: =IF(Parameters!$G$31="All","Yes",IF($C$5="","Yes",IF(ISNUMBER(SEARCH($C$5,Parameters!$G$31)),"Yes","No – N/A for "&$C$5))) -> Yes
A37: =Parameters!$A$32 -> 28 | B37: =Parameters!$B$32 -> Electrical | C37: =Parameters!$C$32 -> Thermocouple heads, compensating cables and connections intact | D37: =Parameters!$D$32 -> Visual | E37: =IF(Parameters!$E$32="","",Parameters!$E$32) | F37: =IF(Parameters!$F$32="Check","OK / Not OK",TRIM(IF(Parameters!$I$32<>"","act <"&Parameters!$I$32&" ","")&IF(Parameters!$J$32<>"","watch <"&Parameters!$J$32&" ","")&IF(Parameters!$K$32<>"","watch >"&Parameters!$K$32&" ","")&IF(Parameters!$L$32<>"","act >"&Parameters!$L$32,""))) -> OK / Not OK | G37: =IF(Parameters!$H$32="","",Parameters!$H$32) | J37: =IF(OR(H37="",I37="",Parameters!$F$32="Check"),"",H37-I37) | K37: =IF(OR(H37="",G37="",Parameters!$F$32="Check"),"",IF(G37=0,H37-G37,(H37-G37)/ABS(G37))) | L37: =IF(LEFT(N37,2)="No","N/A",IF(H37="","",IF(Parameters!$F$32="Check",IF(H37="OK","OK","ACT"),IF(OR(AND(Parameters!$I$32<>"",H37<Parameters!$I$32),AND(Parameters!$L$32<>"",H37>Parameters!$L$32)),"ACT",IF(OR(AND(Parameters!$J$32<>"",H37<Parameters!$J$32),AND(Parameters!$K$32<>"",H37>Parameters!$K$32)),"WATCH","OK"))))) | N37: =IF(Parameters!$G$32="All","Yes",IF($C$5="","Yes",IF(ISNUMBER(SEARCH($C$5,Parameters!$G$32)),"Yes","No – N/A for "&$C$5))) -> Yes
A39: Summary (calculated)
A40: Items for this furnace | F40: =COUNTIF($N$10:$N$37,"Yes") -> 28
A41: Readings entered | F41: =COUNTIF($L$10:$L$37,"OK")+COUNTIF($L$10:$L$37,"WATCH")+COUNTIF($L$10:$L$37,"ACT") -> 0
A42: ACT – outside the action limit | F42: =COUNTIF($L$10:$L$37,"ACT") -> 0
A43: WATCH – beyond the watch limit | F43: =COUNTIF($L$10:$L$37,"WATCH") -> 0
...

Sheet Monthly trend
A1: Mass Wire and Steels Pvt. Ltd. · Bhiwadi · Heat treatment maintenance
A2: Predictive maintenance trend – one sheet per furnace per month
A5: Furnace | E5: Month (first day)
A6: Copy the daily readings of the parameters below into the day rows (or choose other parameters by their number from the Parameters sheet). The rows at the bottom calculate the trend and how many days remain before the action limit.
B8: Parameter no. | C8: 14 | D8: 15 | E8: 4 | F8: 24 | G8: 12 | H8: 7 | I8: 9 | J8: 20 | K8: 3 | L8: 25
B9: Parameter | C9: =IFERROR(INDEX(Parameters!$C$5:$C$32,MATCH(C$8,Parameters!$A$5:$A$32,0)),"") -> Pusher hydraulic pressure during the push | D9: =IFERROR(INDEX(Parameters!$C$5:$C$32,MATCH(D$8,Parameters!$A$5:$A$32,0)),"") -> Push stroke time (one full push) | E9: =IFERROR(INDEX(Parameters!$C$5:$C$32,MATCH(E$8,Parameters!$A$5:$A$32,0)),"") -> Combustion air blower bearing vibration | F9: =IFERROR(INDEX(Parameters!$C$5:$C$32,MATCH(F$8,Parameters!$A$5:$A$32,0)),"") -> Quench agitator motor current (agitation is not monitored: current is the indicator) | G9: =IFERROR(INDEX(Parameters!$C$5:$C$32,MATCH(G$8,Parameters!$A$5:$A$32,0)),"") -> Furnace shell hottest spot (IR scan of walls, roof, doors) | H9: =IFERROR(INDEX(Parameters!$C$5:$C$32,MATCH(H$8,Parameters!$A$5:$A$32,0)),"") -> Highest zone controller output at steady state, hardening chamber | I9: =IFERROR(INDEX(Parameters!$C$5:$C$32,MATCH(I$8,Parameters!$A$5:$A$32,0)),"") -> Largest wall difference (left − right) of a zone, hardening chamber | J9: =IFERROR(INDEX(Parameters!$C$5:$C$32,MATCH(J$8,Parameters!$A$5:$A$32,0)),"") -> Cooling chamber blower motor current | ... L9: =IFERROR(INDEX(Parameters!$C$5:$C$32,MATCH(L$8,Parameters!$A$5:$A$32,0)),"") -> Oil cooler temperature drop (oil in − oil out)
B10: Unit | C10: =IF(IFERROR(INDEX(Parameters!$E$5:$E$32,MATCH(C$8,Parameters!$A$5:$A$32,0)),"")=0,"",IFERROR(INDEX(Parameters!$E$5:$E$32,MATCH(C$8,Parameters!$A$5:$A$32,0)),"")) -> bar | D10: =IF(IFERROR(INDEX(Parameters!$E$5:$E$32,MATCH(D$8,Parameters!$A$5:$A$32,0)),"")=0,"",IFERROR(INDEX(Parameters!$E$5:$E$32,MATCH(D$8,Parameters!$A$5:$A$32,0)),"")) -> s | E10: =IF(IFERROR(INDEX(Parameters!$E$5:$E$32,MATCH(E$8,Parameters!$A$5:$A$32,0)),"")=0,"",IFERROR(INDEX(Parameters!$E$5:$E$32,MATCH(E$8,Parameters!$A$5:$A$32,0)),"")) -> mm/s | F10: =IF(IFERROR(INDEX(Parameters!$E$5:$E$32,MATCH(F$8,Parameters!$A$5:$A$32,0)),"")=0,"",IFERROR(INDEX(Parameters!$E$5:$E$32,MATCH(F$8,Parameters!$A$5:$A$32,0)),"")) -> % FLA | G10: =IF(IFERROR(INDEX(Parameters!$E$5:$E$32,MATCH(G$8,Parameters!$A$5:$A$32,0)),"")=0,"",IFERROR(INDEX(Parameters!$E$5:$E$32,MATCH(G$8,Parameters!$A$5:$A$32,0)),"")) -> °C | H10: =IF(IFERROR(INDEX(Parameters!$E$5:$E$32,MATCH(H$8,Parameters!$A$5:$A$32,0)),"")=0,"",IFERROR(INDEX(Parameters!$E$5:$E$32,MATCH(H$8,Parameters!$A$5:$A$32,0)),"")) -> % | I10: =IF(IFERROR(INDEX(Parameters!$E$5:$E$32,MATCH(I$8,Parameters!$A$5:$A$32,0)),"")=0,"",IFERROR(INDEX(Parameters!$E$5:$E$32,MATCH(I$8,Parameters!$A$5:$A$32,0)),"")) -> °C | J10: =IF(IFERROR(INDEX(Parameters!$E$5:$E$32,MATCH(J$8,Parameters!$A$5:$A$32,0)),"")=0,"",IFERROR(INDEX(Parameters!$E$5:$E$32,MATCH(J$8,Parameters!$A$5:$A$32,0)),"")) -> % FLA | ... L10: =IF(IFERROR(INDEX(Parameters!$E$5:$E$32,MATCH(L$8,Parameters!$A$5:$A$32,0)),"")=0,"",IFERROR(INDEX(Parameters!$E$5:$E$32,MATCH(L$8,Parameters!$A$5:$A$32,0)),"")) -> °C
A11: Day | B11: Date | C11: Reading | D11: Reading | E11: Reading | F11: Reading | G11: Reading | H11: Reading | I11: Reading | J11: Reading | K11: Reading | L11: Reading
A12: 1 | B12: =IF($G$5="","",IF(1>DAY(EOMONTH($G$5,0)),"",$G$5+0))
A13: 2 | B13: =IF($G$5="","",IF(2>DAY(EOMONTH($G$5,0)),"",$G$5+1))
A14: 3 | B14: =IF($G$5="","",IF(3>DAY(EOMONTH($G$5,0)),"",$G$5+2))
A15: 4 | B15: =IF($G$5="","",IF(4>DAY(EOMONTH($G$5,0)),"",$G$5+3))
A16: 5 | B16: =IF($G$5="","",IF(5>DAY(EOMONTH($G$5,0)),"",$G$5+4))
A17: 6 | B17: =IF($G$5="","",IF(6>DAY(EOMONTH($G$5,0)),"",$G$5+5))
A18: 7 | B18: =IF($G$5="","",IF(7>DAY(EOMONTH($G$5,0)),"",$G$5+6))
A19: 8 | B19: =IF($G$5="","",IF(8>DAY(EOMONTH($G$5,0)),"",$G$5+7))
A20: 9 | B20: =IF($G$5="","",IF(9>DAY(EOMONTH($G$5,0)),"",$G$5+8))
A21: 10 | B21: =IF($G$5="","",IF(10>DAY(EOMONTH($G$5,0)),"",$G$5+9))
A22: 11 | B22: =IF($G$5="","",IF(11>DAY(EOMONTH($G$5,0)),"",$G$5+10))
A23: 12 | B23: =IF($G$5="","",IF(12>DAY(EOMONTH($G$5,0)),"",$G$5+11))
A24: 13 | B24: =IF($G$5="","",IF(13>DAY(EOMONTH($G$5,0)),"",$G$5+12))
A25: 14 | B25: =IF($G$5="","",IF(14>DAY(EOMONTH($G$5,0)),"",$G$5+13))
A26: 15 | B26: =IF($G$5="","",IF(15>DAY(EOMONTH($G$5,0)),"",$G$5+14))
A27: 16 | B27: =IF($G$5="","",IF(16>DAY(EOMONTH($G$5,0)),"",$G$5+15))
A28: 17 | B28: =IF($G$5="","",IF(17>DAY(EOMONTH($G$5,0)),"",$G$5+16))
A29: 18 | B29: =IF($G$5="","",IF(18>DAY(EOMONTH($G$5,0)),"",$G$5+17))
A30: 19 | B30: =IF($G$5="","",IF(19>DAY(EOMONTH($G$5,0)),"",$G$5+18))
A31: 20 | B31: =IF($G$5="","",IF(20>DAY(EOMONTH($G$5,0)),"",$G$5+19))
A32: 21 | B32: =IF($G$5="","",IF(21>DAY(EOMONTH($G$5,0)),"",$G$5+20))
A33: 22 | B33: =IF($G$5="","",IF(22>DAY(EOMONTH($G$5,0)),"",$G$5+21))
A34: 23 | B34: =IF($G$5="","",IF(23>DAY(EOMONTH($G$5,0)),"",$G$5+22))
A35: 24 | B35: =IF($G$5="","",IF(24>DAY(EOMONTH($G$5,0)),"",$G$5+23))
A36: 25 | B36: =IF($G$5="","",IF(25>DAY(EOMONTH($G$5,0)),"",$G$5+24))
A37: 26 | B37: =IF($G$5="","",IF(26>DAY(EOMONTH($G$5,0)),"",$G$5+25))
A38: 27 | B38: =IF($G$5="","",IF(27>DAY(EOMONTH($G$5,0)),"",$G$5+26))
A39: 28 | B39: =IF($G$5="","",IF(28>DAY(EOMONTH($G$5,0)),"",$G$5+27))
A40: 29 | B40: =IF($G$5="","",IF(29>DAY(EOMONTH($G$5,0)),"",$G$5+28))
A41: 30 | B41: =IF($G$5="","",IF(30>DAY(EOMONTH($G$5,0)),"",$G$5+29))
A42: 31 | B42: =IF($G$5="","",IF(31>DAY(EOMONTH($G$5,0)),"",$G$5+30))
A43: Normal | C43: =IF(IFERROR(INDEX(Parameters!$H$5:$H$32,MATCH(C$8,Parameters!$A$5:$A$32,0)),"")="","",IFERROR(INDEX(Parameters!$H$5:$H$32,MATCH(C$8,Parameters!$A$5:$A$32,0)),"")) -> 80 | D43: =IF(IFERROR(INDEX(Parameters!$H$5:$H$32,MATCH(D$8,Parameters!$A$5:$A$32,0)),"")="","",IFERROR(INDEX(Parameters!$H$5:$H$32,MATCH(D$8,Parameters!$A$5:$A$32,0)),"")) -> 30 | E43: =IF(IFERROR(INDEX(Parameters!$H$5:$H$32,MATCH(E$8,Parameters!$A$5:$A$32,0)),"")="","",IFERROR(INDEX(Parameters!$H$5:$H$32,MATCH(E$8,Parameters!$A$5:$A$32,0)),"")) -> 1.5 | F43: =IF(IFERROR(INDEX(Parameters!$H$5:$H$32,MATCH(F$8,Parameters!$A$5:$A$32,0)),"")="","",IFERROR(INDEX(Parameters!$H$5:$H$32,MATCH(F$8,Parameters!$A$5:$A$32,0)),"")) -> 70 | G43: =IF(IFERROR(INDEX(Parameters!$H$5:$H$32,MATCH(G$8,Parameters!$A$5:$A$32,0)),"")="","",IFERROR(INDEX(Parameters!$H$5:$H$32,MATCH(G$8,Parameters!$A$5:$A$32,0)),"")) -> 70 | H43: =IF(IFERROR(INDEX(Parameters!$H$5:$H$32,MATCH(H$8,Parameters!$A$5:$A$32,0)),"")="","",IFERROR(INDEX(Parameters!$H$5:$H$32,MATCH(H$8,Parameters!$A$5:$A$32,0)),"")) -> 55 | I43: =IF(IFERROR(INDEX(Parameters!$H$5:$H$32,MATCH(I$8,Parameters!$A$5:$A$32,0)),"")="","",IFERROR(INDEX(Parameters!$H$5:$H$32,MATCH(I$8,Parameters!$A$5:$A$32,0)),"")) -> 0 | J43: =IF(IFERROR(INDEX(Parameters!$H$5:$H$32,MATCH(J$8,Parameters!$A$5:$A$32,0)),"")="","",IFERROR(INDEX(Parameters!$H$5:$H$32,MATCH(J$8,Parameters!$A$5:$A$32,0)),"")) -> 70 | ... L43: =IF(IFERROR(INDEX(Parameters!$H$5:$H$32,MATCH(L$8,Parameters!$A$5:$A$32,0)),"")="","",IFERROR(INDEX(Parameters!$H$5:$H$32,MATCH(L$8,Parameters!$A$5:$A$32,0)),"")) -> 8
...

Sheet Parameters
A1: Mass Wire and Steels Pvt. Ltd. · Bhiwadi · Furnace predictive maintenance
A2: Parameters, normal values and limits – one list for all four furnaces (edit the yellow cells; the daily checksheet and the trend sheet read them from here)
A3: Values are TYPICAL starting points, not measured on your furnaces: replace the normal value with the average of the first 2–4 weeks of readings and set the limits from the equipment manuals.
A4: No. | B4: Area | C4: Parameter | D4: Method / instrument | E4: Unit | F4: Kind | G4: Applies to | H4: Normal (baseline) | I4: Act if below | J4: Watch if below | K4: Watch if above | L4: Act if above | M4: What a change predicts
A5: 1 | B5: Combustion | C5: Main gas pressure at the furnace gas train | D5: Gas train gauge | E5: mbar | F5: Value | G5: All | H5: 40 | I5: 30 | J5: 34 | K5: 46 | L5: 50 | M5: Regulator / filter blockage; supply problems before a flame failure
A6: 2 | B6: Combustion | C6: Combustion air pressure after the blower | D6: Air header gauge | E6: mbar | F6: Value | G6: All | H6: 60 | I6: 48 | J6: 53 | K6: 70 | L6: 75 | M6: Blower / filter / damper deterioration; air-fuel ratio drift
A7: 3 | B7: Combustion | C7: Combustion air blower motor current | D7: Clamp meter or panel ammeter (% of rated current) | E7: % FLA | F7: Value | G7: All | H7: 70 | I7: 40 | J7: 55 | K7: 85 | L7: 95 | M7: Bearing / impeller / belt problems, blocked intake
A8: 4 | B8: Combustion | C8: Combustion air blower bearing vibration | D8: Handheld vibration meter, velocity RMS | E8: mm/s | F8: Value | G8: All | H8: 1.5 | K8: 2.8 | L8: 4.5 | M8: Bearing wear, imbalance, looseness (ISO 10816-3 group 2 rigid zones, to confirm)
A9: 5 | B9: Combustion | C9: Combustion air blower bearing temperature | D9: IR thermometer | E9: °C | F9: Value | G9: All | H9: 50 | K9: 70 | L9: 85 | M9: Lubrication failure, bearing wear
A10: 6 | B10: Combustion | C10: Burner flame failures / lockouts in the last 24 h | D10: Alarm log (CALOR → Alarms) / burner controller | E10: count | F10: Value | G10: All | H10: 0 | K10: 1 | L10: 3 | M10: Igniter / flame sensor / nozzle fouling
A11: 7 | B11: Combustion | C11: Highest zone controller output at steady state, hardening chamber | D11: SCADA / controller display | E11: % | F11: Value | G11: All | H11: 55 | K11: 75 | L11: 90 | M11: Burner capacity loss, refractory heat loss, air leaks: rising output for the same set value
A12: 8 | B12: Combustion | C12: Highest zone controller output at steady state, tempering chamber | D12: SCADA / controller display | E12: % | F12: Value | G12: All | H12: 45 | K12: 70 | L12: 85 | M12: As above, tempering chamber
A13: 9 | B13: Temperature | C13: Largest wall difference (left − right) of a zone, hardening chamber | D13: SCADA (TC odd = right, even = left) | E13: °C | F13: Value | G13: All | H13: 0 | I13: -8 | J13: -5 | K13: 5 | L13: 8 | M13: Burner imbalance on one wall or thermocouple drift (SAT due)
A14: 10 | B14: Temperature | C14: Largest wall difference (left − right) of a zone, tempering chamber | D14: SCADA (TC odd = right, even = left) | E14: °C | F14: Value | G14: All | H14: 0 | I14: -8 | J14: -5 | K14: 5 | L14: 8 | M14: As above, tempering chamber
A15: 11 | B15: Temperature | C15: Over-temperature controller reading vs control thermocouple (difference) | D15: Panel displays | E15: °C | F15: Value | G15: All | H15: 0 | I15: -8 | J15: -5 | K15: 5 | L15: 8 | M15: Drift of the over-temperature sensor or the control thermocouple
A16: 12 | B16: Refractory | C16: Furnace shell hottest spot (IR scan of walls, roof, doors) | D16: IR thermometer / camera, same route daily | E16: °C | F16: Value | G16: All | H16: 70 | K16: 100 | L16: 120 | M16: Refractory / insulation failure before a burn-through
A17: 13 | B17: Refractory | C17: Door seals and flame curtains intact, no flame out of doors | D17: Visual | F17: Check | G17: All | M17: Seal / curtain wear, heat loss, decarburization risk
A18: 14 | B18: Pusher | C18: Pusher hydraulic pressure during the push | D18: Hydraulic gauge at mid-stroke | E18: bar | F18: Value | G18: All | H18: 80 | K18: 110 | L18: 130 | M18: Rising friction: hearth / rail wear, tray distortion, scale build-up, jam risk
A19: 15 | B19: Pusher | C19: Push stroke time (one full push) | D19: Stopwatch / PLC | E19: s | F19: Value | G19: All | H19: 30 | K19: 36 | L19: 40 | M19: Pump wear, internal leakage, valve problems
A20: 16 | B20: Pusher | C20: Hydraulic oil temperature | D20: Tank thermometer | E20: °C | F20: Value | G20: All | H20: 45 | K20: 55 | L20: 60 | M20: Cooler fouling, pump wear, oil degradation
A21: 17 | B21: Pusher | C21: Hydraulic oil level and no leaks | D21: Sight glass / visual | F21: Check | G21: All | M21: Seal and hose wear
A22: 18 | B22: Transfer | C22: Extractor / rail transfer drive motor current | D22: Clamp meter or panel ammeter (% of rated) | E22: % FLA | F22: Value | G22: All | H22: 60 | K22: 80 | L22: 90 | M22: Rail / roller / chain wear, misalignment
A23: 19 | B23: Transfer | C23: Chains, rails and rollers: lubricated, no abnormal noise | D23: Visual / listen | F23: Check | G23: All | M23: Lubrication and wear
A24: 20 | B24: Controlled cooling | C24: Cooling chamber blower motor current | D24: Clamp meter or panel ammeter (% of rated) | E24: % FLA | F24: Value | G24: All | H24: 70 | I24: 45 | J24: 55 | K24: 85 | L24: 95 | M24: Blower / damper / filter problems: slower controlled cooling
A25: 21 | B25: Controlled cooling | C25: Cooling chamber blower bearing vibration | D25: Handheld vibration meter, velocity RMS | E25: mm/s | F25: Value | G25: All | H25: 1.5 | K25: 2.8 | L25: 4.5 | M25: Bearing wear, imbalance
A26: 22 | B26: Quench | C26: Water quench tank temperature at the start of the shift | D26: Tank indicator / thermometer | E26: °C | F26: Value | G26: F-01 | H26: 28 | K26: 32 | L26: 35 | M26: Cooling water / heat exchanger capacity loss
A27: 23 | B27: Quench | C27: Oil quench tank temperature at the start of the shift | D27: Tank indicator / thermometer | E27: °C | F27: Value | G27: F-02 | H27: 62 | I27: 50 | J27: 54 | K27: 76 | L27: 80 | M27: Heater / cooler control problems
A28: 24 | B28: Quench | C28: Quench agitator motor current (agitation is not monitored: current is the indicator) | D28: Clamp meter or panel ammeter (% of rated) | E28: % FLA | F28: Value | G28: F-01, F-02 | H28: 70 | I28: 45 | J28: 55 | K28: 90 | L28: 100 | M28: Falling current: impeller wear / loss, belt slip; rising: bearing / jamming
A29: 25 | B29: Quench | C29: Oil cooler temperature drop (oil in − oil out) | D29: Thermometers at the cooler | E29: °C | F29: Value | G29: F-02 | H29: 8 | I29: 3 | J29: 5 | M29: Cooler fouling: slower heat removal before the oil overheats
A30: 26 | B30: Quench | C30: Quench elevator / conveyor: no abnormal noise, chain tension | D30: Visual / listen | F30: Check | G30: F-01, F-02 | M30: Chain / sprocket wear
A31: 27 | B31: Electrical | C31: Control panel internal temperature | D31: Panel thermometer / IR | E31: °C | F31: Value | G31: All | H31: 35 | K31: 40 | L31: 45 | M31: Panel cooling failure, overheating components
A32: 28 | B32: Electrical | C32: Thermocouple heads, compensating cables and connections intact | D32: Visual | F32: Check | G32: All | M32: Damaged cables, loose connections (reading drift)

Sheet Example daily (F-02)
A1: Mass Wire and Steels Pvt. Ltd. · Bhiwadi · Heat treatment maintenance
A2: Daily predictive maintenance checksheet – furnace | K2: Form F-MT-01 · Rev 0
K3: One sheet per furnace per day
B5: Furnace | C5: F-02 | F5: Date | G5: 46315 | J5: Shift | K5: A (06:00-14:00)
B6: Furnace state | C6: Running (steady state) | F6: Checked by | G6: Maintenance fitter (example) | J6: Instruments used | K6: Clamp meter CM-03, vibration meter VM-01, IR gun IR-02
A7: Take the readings at the same time and place every day, with the furnace at steady state where the item says so. Enter yesterday's reading to see the change (or copy it from yesterday's sheet).
A9: No. | B9: Area | C9: Parameter | D9: Method / instrument | E9: Unit | F9: Limits | G9: Normal | H9: Reading today | I9: Reading yesterday | J9: Change since yesterday | K9: vs normal | L9: Status | M9: Action / remarks (work order no.) | N9: Applicable
A10: =Parameters!$A$5 -> 1 | B10: =Parameters!$B$5 -> Combustion | C10: =Parameters!$C$5 -> Main gas pressure at the furnace gas train | D10: =Parameters!$D$5 -> Gas train gauge | E10: =IF(Parameters!$E$5="","",Parameters!$E$5) -> mbar | F10: =IF(Parameters!$F$5="Check","OK / Not OK",TRIM(IF(Parameters!$I$5<>"","act <"&Parameters!$I$5&" ","")&IF(Parameters!$J$5<>"","watch <"&Parameters!$J$5&" ","")&IF(Parameters!$K$5<>"","watch >"&Parameters!$K$5&" ","")&IF(Parameters!$L$5<>"","act >"&Parameters!$L$5,""))) -> act <30 watch <34 watch >46 act >50 | G10: =IF(Parameters!$H$5="","",Parameters!$H$5) -> 40 | H10: 41 | I10: 40 | J10: =IF(OR(H10="",I10="",Parameters!$F$5="Check"),"",H10-I10) -> 1 | K10: =IF(OR(H10="",G10="",Parameters!$F$5="Check"),"",IF(G10=0,H10-G10,(H10-G10)/ABS(G10))) -> 0.025 | L10: =IF(LEFT(N10,2)="No","N/A",IF(H10="","",IF(Parameters!$F$5="Check",IF(H10="OK","OK","ACT"),IF(OR(AND(Parameters!$I$5<>"",H10<Parameters!$I$5),AND(Parameters!$L$5<>"",H10>Parameters!$L$5)),"ACT",IF(OR(AND(Parameters!$J$5<>"",H10<Parameters!$J$5),AND(Parameters!$K$5<>"",H10>Parameters!$K$5)),"WATCH","OK"))))) -> OK | N10: =IF(Parameters!$G$5="All","Yes",IF($C$5="","Yes",IF(ISNUMBER(SEARCH($C$5,Parameters!$G$5)),"Yes","No – N/A for "&$C$5))) -> Yes
A11: =Parameters!$A$6 -> 2 | B11: =Parameters!$B$6 -> Combustion | C11: =Parameters!$C$6 -> Combustion air pressure after the blower | D11: =Parameters!$D$6 -> Air header gauge | E11: =IF(Parameters!$E$6="","",Parameters!$E$6) -> mbar | F11: =IF(Parameters!$F$6="Check","OK / Not OK",TRIM(IF(Parameters!$I$6<>"","act <"&Parameters!$I$6&" ","")&IF(Parameters!$J$6<>"","watch <"&Parameters!$J$6&" ","")&IF(Parameters!$K$6<>"","watch >"&Parameters!$K$6&" ","")&IF(Parameters!$L$6<>"","act >"&Parameters!$L$6,""))) -> act <48 watch <53 watch >70 act >75 | G11: =IF(Parameters!$H$6="","",Parameters!$H$6) -> 60 | H11: 59 | I11: 60 | J11: =IF(OR(H11="",I11="",Parameters!$F$6="Check"),"",H11-I11) -> -1 | K11: =IF(OR(H11="",G11="",Parameters!$F$6="Check"),"",IF(G11=0,H11-G11,(H11-G11)/ABS(G11))) -> -0.016666667 | L11: =IF(LEFT(N11,2)="No","N/A",IF(H11="","",IF(Parameters!$F$6="Check",IF(H11="OK","OK","ACT"),IF(OR(AND(Parameters!$I$6<>"",H11<Parameters!$I$6),AND(Parameters!$L$6<>"",H11>Parameters!$L$6)),"ACT",IF(OR(AND(Parameters!$J$6<>"",H11<Parameters!$J$6),AND(Parameters!$K$6<>"",H11>Parameters!$K$6)),"WATCH","OK"))))) -> OK | N11: =IF(Parameters!$G$6="All","Yes",IF($C$5="","Yes",IF(ISNUMBER(SEARCH($C$5,Parameters!$G$6)),"Yes","No – N/A for "&$C$5))) -> Yes
A12: =Parameters!$A$7 -> 3 | B12: =Parameters!$B$7 -> Combustion | C12: =Parameters!$C$7 -> Combustion air blower motor current | D12: =Parameters!$D$7 -> Clamp meter or panel ammeter (% of rated current) | E12: =IF(Parameters!$E$7="","",Parameters!$E$7) -> % FLA | F12: =IF(Parameters!$F$7="Check","OK / Not OK",TRIM(IF(Parameters!$I$7<>"","act <"&Parameters!$I$7&" ","")&IF(Parameters!$J$7<>"","watch <"&Parameters!$J$7&" ","")&IF(Parameters!$K$7<>"","watch >"&Parameters!$K$7&" ","")&IF(Parameters!$L$7<>"","act >"&Parameters!$L$7,""))) -> act <40 watch <55 watch >85 act >95 | G12: =IF(Parameters!$H$7="","",Parameters!$H$7) -> 70 | H12: 74 | I12: 72 | J12: =IF(OR(H12="",I12="",Parameters!$F$7="Check"),"",H12-I12) -> 2 | K12: =IF(OR(H12="",G12="",Parameters!$F$7="Check"),"",IF(G12=0,H12-G12,(H12-G12)/ABS(G12))) -> 0.057142857 | L12: =IF(LEFT(N12,2)="No","N/A",IF(H12="","",IF(Parameters!$F$7="Check",IF(H12="OK","OK","ACT"),IF(OR(AND(Parameters!$I$7<>"",H12<Parameters!$I$7),AND(Parameters!$L$7<>"",H12>Parameters!$L$7)),"ACT",IF(OR(AND(Parameters!$J$7<>"",H12<Parameters!$J$7),AND(Parameters!$K$7<>"",H12>Parameters!$K$7)),"WATCH","OK"))))) -> OK | N12: =IF(Parameters!$G$7="All","Yes",IF($C$5="","Yes",IF(ISNUMBER(SEARCH($C$5,Parameters!$G$7)),"Yes","No – N/A for "&$C$5))) -> Yes
A13: =Parameters!$A$8 -> 4 | B13: =Parameters!$B$8 -> Combustion | C13: =Parameters!$C$8 -> Combustion air blower bearing vibration | D13: =Parameters!$D$8 -> Handheld vibration meter, velocity RMS | E13: =IF(Parameters!$E$8="","",Parameters!$E$8) -> mm/s | F13: =IF(Parameters!$F$8="Check","OK / Not OK",TRIM(IF(Parameters!$I$8<>"","act <"&Parameters!$I$8&" ","")&IF(Parameters!$J$8<>"","watch <"&Parameters!$J$8&" ","")&IF(Parameters!$K$8<>"","watch >"&Parameters!$K$8&" ","")&IF(Parameters!$L$8<>"","act >"&Parameters!$L$8,""))) -> watch >2.8 act >4.5 | G13: =IF(Parameters!$H$8="","",Parameters!$H$8) -> 1.5 | H13: 2.9 | I13: 2.6 | J13: =IF(OR(H13="",I13="",Parameters!$F$8="Check"),"",H13-I13) -> 0.3 | K13: =IF(OR(H13="",G13="",Parameters!$F$8="Check"),"",IF(G13=0,H13-G13,(H13-G13)/ABS(G13))) -> 0.93333333 | L13: =IF(LEFT(N13,2)="No","N/A",IF(H13="","",IF(Parameters!$F$8="Check",IF(H13="OK","OK","ACT"),IF(OR(AND(Parameters!$I$8<>"",H13<Parameters!$I$8),AND(Parameters!$L$8<>"",H13>Parameters!$L$8)),"ACT",IF(OR(AND(Parameters!$J$8<>"",H13<Parameters!$J$8),AND(Parameters!$K$8<>"",H13>Parameters!$K$8)),"WATCH","OK"))))) -> WATCH | M13: Vibration rising for 3 weeks – see the trend sheet; spectrum check booked (WO-1187) | N13: =IF(Parameters!$G$8="All","Yes",IF($C$5="","Yes",IF(ISNUMBER(SEARCH($C$5,Parameters!$G$8)),"Yes","No – N/A for "&$C$5))) -> Yes
A14: =Parameters!$A$9 -> 5 | B14: =Parameters!$B$9 -> Combustion | C14: =Parameters!$C$9 -> Combustion air blower bearing temperature | D14: =Parameters!$D$9 -> IR thermometer | E14: =IF(Parameters!$E$9="","",Parameters!$E$9) -> °C | F14: =IF(Parameters!$F$9="Check","OK / Not OK",TRIM(IF(Parameters!$I$9<>"","act <"&Parameters!$I$9&" ","")&IF(Parameters!$J$9<>"","watch <"&Parameters!$J$9&" ","")&IF(Parameters!$K$9<>"","watch >"&Parameters!$K$9&" ","")&IF(Parameters!$L$9<>"","act >"&Parameters!$L$9,""))) -> watch >70 act >85 | G14: =IF(Parameters!$H$9="","",Parameters!$H$9) -> 50 | H14: 62 | I14: 60 | J14: =IF(OR(H14="",I14="",Parameters!$F$9="Check"),"",H14-I14) -> 2 | K14: =IF(OR(H14="",G14="",Parameters!$F$9="Check"),"",IF(G14=0,H14-G14,(H14-G14)/ABS(G14))) -> 0.24 | L14: =IF(LEFT(N14,2)="No","N/A",IF(H14="","",IF(Parameters!$F$9="Check",IF(H14="OK","OK","ACT"),IF(OR(AND(Parameters!$I$9<>"",H14<Parameters!$I$9),AND(Parameters!$L$9<>"",H14>Parameters!$L$9)),"ACT",IF(OR(AND(Parameters!$J$9<>"",H14<Parameters!$J$9),AND(Parameters!$K$9<>"",H14>Parameters!$K$9)),"WATCH","OK"))))) -> OK | N14: =IF(Parameters!$G$9="All","Yes",IF($C$5="","Yes",IF(ISNUMBER(SEARCH($C$5,Parameters!$G$9)),"Yes","No – N/A for "&$C$5))) -> Yes
