Workbook

Sheet Report
A1: MASS WIRE AND STEELS PVT. LTD., BHIWADI
A2: Daily production report: pusher furnace line
A3: Format MWSPL-F-PROD-01 rev 00 · one workbook per furnace and production day · enter the trays in the Tray log, the pauses of the push cycle in Holds, set-value / push changes in Parameter changes.
A5: Report identification | D5: Production in this day (trays out of the tempering chamber) | G5: Sign-off
A6: Furnace | B6: F-02 | D6: Trays out (loaded and mixed) | E6: =COUNTIFS('Tray log'!$Y$7:$Y$306,$B$7,'Tray log'!$B$7:$B$306,"Loaded")+COUNTIFS('Tray log'!$Y$7:$Y$306,$B$7,'Tray log'!$B$7:$B$306,"Mixed") -> 43 | G6: Entered by (shift operator) | H6: A. Kumar (example)
A7: Production date (day of exit) | B7: 46320 | D7: Empty trays out (separators) | E7: =COUNTIFS('Tray log'!$Y$7:$Y$306,$B$7,'Tray log'!$B$7:$B$306,"Empty") -> 2 | G7: Shift in-charge: shift A
A8: Production day from | B8: =B7+Settings!$B$6 -> 46320.333 | D8: Pieces out | E8: =SUMIFS('Tray log'!$J$7:$J$306,'Tray log'!$Y$7:$Y$306,$B$7)+SUMIFS('Tray log'!$N$7:$N$306,'Tray log'!$Y$7:$Y$306,$B$7) -> 1731 | G8: Shift in-charge: shift B
A9: Production day to | B9: =B8+1 -> 46321.333 | D9: Net weight out (kg, calculated) | E9: =SUMIFS('Tray log'!$R$7:$R$306,'Tray log'!$Y$7:$Y$306,$B$7) -> 3875.4 | G9: Shift in-charge: shift C
A10: Report no. | B10: PR-0001 | D10: of which hardening & tempering (kg) | E10: =SUMIFS('Tray log'!$R$7:$R$306,'Tray log'!$Y$7:$Y$306,$B$7,'Tray log'!$O$7:$O$306,"HT") -> 1944 | G10: Checked by (Production Manager)
A11: Line start: first tray of the tray log enters | B11: 46320.25 | D11: of which isothermal annealing (kg) | E11: =SUMIFS('Tray log'!$R$7:$R$306,'Tray log'!$Y$7:$Y$306,$B$7,'Tray log'!$O$7:$O$306,"IA") -> 1344 | G11: Approved on
A12: Push time at the start (min) | B12: 9 | D12: of which normalizing (kg) | E12: =SUMIFS('Tray log'!$R$7:$R$306,'Tray log'!$Y$7:$Y$306,$B$7,'Tray log'!$O$7:$O$306,"NORM") -> 587.4 | G12: Remarks
D13: Rework trays out (re-heat-treatment) | E13: =COUNTIFS('Tray log'!$Y$7:$Y$306,$B$7,'Tray log'!$S$7:$S$306,"?*") -> 4
D14: Trays with a check flag | E14: =COUNTIFS('Tray log'!$Y$7:$Y$306,$B$7,'Tray log'!$AA$7:$AA$306,"?*") -> 0
D15: Push cycle on hold in the day (min) | E15: =SUMIFS(Holds!$F$7:$F$46,Holds!$B$7:$B$46,">="&$B$8,Holds!$B$7:$B$46,"<"&$B$9) -> 40
D16: Holds still open (no restart time) | E16: =COUNTIFS(Holds!$B$7:$B$46,"<>",Holds!$C$7:$C$46,"") -> 0
D17: Parameter changes in the day | E17: =COUNTIFS('Parameter changes'!$B$7:$B$46,">="&$B$8,'Parameter changes'!$B$7:$B$46,"<"&$B$9) -> 1
D18: Last tray out (calculated) | E18: =IF(B6="","",_xlfn.MAXIFS('Tray log'!$W$7:$W$306,'Tray log'!$Y$7:$Y$306,$B$7)) -> 46320.763
D19: Last tray out (actual, from the unloading) | E19: 46320.765
D20: Difference actual − calculated (min) | E20: =IF(OR(E19="",E18="",E18=0),"",ROUND((E19-E18)*1440,0)) -> 3
D21: Timing check | E21: =IF(E20="","",IF(ABS(E20)<=Settings!$B$11,"OK","Check start, push, push changes, holds")) -> OK
A23: Batches out in this day
A24: See the Batches sheet: one row per part + batch + heat (rework separately), with trays, pieces and kg out in this day, entry, calculated and actual last tray out, weighed weight.
A26: How to use this format
A27: Yellow cells with blue text | B27: Entries. Type or pick from the drop-down.
A28: Grey cells with black text | B28: Formulas: do not type over them (the gap of an isothermal annealing part on the Parts sheet is the one exception).
A29: Example rows | B29: Every sheet holds a few example rows (part numbers EX-…, names marked example). Delete them before the first real report.
A30: 1 · Parts | B30: Copy each part from its process specification in force: process, pieces per tray, part weight, push time, gap between the chambers.
A31: 2 · Report | B31: Furnace, production date, report no., the time the first tray of the tray log entered and the push time then.
A32: 3 · Tray log | B32: One row per tray in the order the trays enter the hardening chamber, including empty separator trays. A mixed tray uses the second part columns. Type an actual entry time only for a tray that entered off the push cycle; change the push time on the tray from which it changed.
A33: 4 · Holds | B33: Every pause of the push cycle (from, to, reason). The push timer stops during a hold: the formulas shift the following trays.
A34: 5 · Parameter changes | B34: Set value, push, controlled cooling or quench changes with time, from / to and reason.
A35: 6 · Batches | B35: One row per part + batch + heat; record the actual time the last tray of the batch left the tempering chamber and the weighed weight.
A36: Line timing | B36: Out of the hardening chamber = entry of the tray 13 positions later; out of the tempering chamber = entry of the tray 25 positions later + the gap (transfer 18 min for HT / normalizing, the controlled cooling cycle for isothermal annealing). Rows near the end of the log, without 25 trays after them, are estimated from the push time (Basis = estimate).
A37: Production day | B37: A tray counts in the day in which it leaves the tempering chamber, from 08:00 to 08:00 the next day, whichever day it was loaded.
A38: N/A | B38: "N/A" means not available: type it where a batch, heat or heat code is not known. It is an entry, not an identity: two N/A batches are not the same batch.

Sheet Tray log
A1: MASS WIRE AND STEELS PVT. LTD., BHIWADI
A2: Tray log: one row per tray, in the order the trays enter the hardening chamber
A3: Empty separator trays are rows too (type Empty). Times are calculated from the line start, the push time and the holds; type an actual entry only for a tray off the cycle.
A6: Tray no. | B6: Tray type | C6: Actual entry (only if off cycle) | D6: Push time from this tray (min) | E6: Entry into hardening (calc) | F6: Part no. 1 | G6: Batch no. 1 | H6: Heat no. 1 | I6: Heat code 1 | J6: Pieces 1 | K6: Part no. 2 (mixed tray) | L6: Batch no. 2 | M6: Heat no. 2 | N6: Pieces 2 | O6: Process | P6: Pieces per tray (spec) | Q6: Tray load (% of spec) | R6: Net weight (kg) | S6: Rework ref. (NCR / report) | T6: Rework reason | U6: Gap (min) | V6: Out of hardening (calc) | W6: Out of tempering (calc) | X6: Basis | Y6: Production day (exit) | Z6: Note | AA6: Check flags
A7: =IF(B7="","",COUNTA(B$7:B7)) -> 1 | B7: Loaded | D7: =Report!B12 -> 9 | E7: =IF(B7="","",IF(C7<>"",C7,Report!$B$11)) -> 46320.25 | F7: EX-1001 | G7: B-102 | H7: H-5521 | I7: C7 | J7: 60 | O7: =IF(F7="","",IFERROR(INDEX(Parts!$C$6:$C$45,MATCH(F7,Parts!$A$6:$A$45,0)),"")) -> HT | P7: =IF(F7="","",IFERROR(INDEX(Parts!$E$6:$E$45,MATCH(F7,Parts!$A$6:$A$45,0)),"")) -> 60 | Q7: =IF(OR(J7="",P7="",P7=0),"",J7/P7+IF(OR(N7="",K7=""),0,IFERROR(N7/INDEX(Parts!$E$6:$E$45,MATCH(K7,Parts!$A$6:$A$45,0)),0))) -> 1 | R7: =IF(B7="","",IF(J7="",0,J7*IFERROR(INDEX(Parts!$F$6:$F$45,MATCH(F7,Parts!$A$6:$A$45,0)),0))+IF(N7="",0,N7*IFERROR(INDEX(Parts!$F$6:$F$45,MATCH(K7,Parts!$A$6:$A$45,0)),0))) -> 108 | U7: =IF(B7="","",IF(F7="",Settings!$B$9,IFERROR(INDEX(Parts!$H$6:$H$45,MATCH(F7,Parts!$A$6:$A$45,0))+0,Settings!$B$9))) -> 18 | V7: =IF(B7="","",IF(INDEX($E$7:$E$336,ROW()-6+Settings!$B$7)<>"",INDEX($E$7:$E$336,ROW()-6+Settings!$B$7),E7+Settings!$B$7*D7/1440)) -> 46320.334 | W7: =IF(B7="","",IF(INDEX($E$7:$E$336,ROW()-6+Settings!$B$7+Settings!$B$8)<>"",INDEX($E$7:$E$336,ROW()-6+Settings!$B$7+Settings!$B$8),E7+(Settings!$B$7+Settings!$B$8)*D7/1440)+U7/1440) -> 46320.458 | X7: =IF(B7="","",IF(INDEX($E$7:$E$336,ROW()-6+Settings!$B$7+Settings!$B$8)<>"","line","estimate")) -> line | Y7: =IF(B7="","",INT(W7-Settings!$B$6)) -> 46320 | Z7: Example rows: delete before use | AA7: =IF(B7="","",IF(AND(B7<>"Empty",F7=""),"part missing; ","")&IF(AND(F7<>"",J7=""),"pieces missing; ","")&IF(AND(F7<>"",O7=""),"part not on the Parts sheet; ","")&IF(AND(B7="Empty",OR(F7<>"",K7<>"")),"empty tray with parts; ","")&IF(AND(B7="Loaded",K7<>""),"second part: type Mixed; ","")&IF(AND(Q7<>"",N(Q7)>1),"over 100 % of the spec load; ","")&IF(N(R7)>Settings!$B$10,"over the tray maximum (kg); ","")&IF(AND(K7<>"",IFERROR(INDEX(Parts!$C$6:$C$45,MATCH(K7,Parts!$A$6:$A$45,0)),O7)<>O7),"different processes in one tray; ","")&IF(AND(S7<>"",T7=""),"rework reason missing; ",""))
A8: =IF(B8="","",COUNTA(B$7:B8)) -> 2 | B8: Loaded | D8: =IF(B8="","",IF(D7="",Report!$B$12,D7)) -> 9 | E8: =IF(B8="","",IF(C8<>"",C8,E7+D7/1440+SUMIFS(Holds!$F$7:$F$46,Holds!$B$7:$B$46,">="&E7,Holds!$B$7:$B$46,"<"&E7+D7/1440)/1440)) -> 46320.256 | F8: EX-1001 | G8: B-102 | H8: H-5521 | I8: C7 | J8: 60 | O8: =IF(F8="","",IFERROR(INDEX(Parts!$C$6:$C$45,MATCH(F8,Parts!$A$6:$A$45,0)),"")) -> HT | P8: =IF(F8="","",IFERROR(INDEX(Parts!$E$6:$E$45,MATCH(F8,Parts!$A$6:$A$45,0)),"")) -> 60 | Q8: =IF(OR(J8="",P8="",P8=0),"",J8/P8+IF(OR(N8="",K8=""),0,IFERROR(N8/INDEX(Parts!$E$6:$E$45,MATCH(K8,Parts!$A$6:$A$45,0)),0))) -> 1 | R8: =IF(B8="","",IF(J8="",0,J8*IFERROR(INDEX(Parts!$F$6:$F$45,MATCH(F8,Parts!$A$6:$A$45,0)),0))+IF(N8="",0,N8*IFERROR(INDEX(Parts!$F$6:$F$45,MATCH(K8,Parts!$A$6:$A$45,0)),0))) -> 108 | U8: =IF(B8="","",IF(F8="",Settings!$B$9,IFERROR(INDEX(Parts!$H$6:$H$45,MATCH(F8,Parts!$A$6:$A$45,0))+0,Settings!$B$9))) -> 18 | V8: =IF(B8="","",IF(INDEX($E$7:$E$336,ROW()-6+Settings!$B$7)<>"",INDEX($E$7:$E$336,ROW()-6+Settings!$B$7),E8+Settings!$B$7*D8/1440)) -> 46320.341 | W8: =IF(B8="","",IF(INDEX($E$7:$E$336,ROW()-6+Settings!$B$7+Settings!$B$8)<>"",INDEX($E$7:$E$336,ROW()-6+Settings!$B$7+Settings!$B$8),E8+(Settings!$B$7+Settings!$B$8)*D8/1440)+U8/1440) -> 46320.465 | X8: =IF(B8="","",IF(INDEX($E$7:$E$336,ROW()-6+Settings!$B$7+Settings!$B$8)<>"","line","estimate")) -> line | Y8: =IF(B8="","",INT(W8-Settings!$B$6)) -> 46320 | AA8: =IF(B8="","",IF(AND(B8<>"Empty",F8=""),"part missing; ","")&IF(AND(F8<>"",J8=""),"pieces missing; ","")&IF(AND(F8<>"",O8=""),"part not on the Parts sheet; ","")&IF(AND(B8="Empty",OR(F8<>"",K8<>"")),"empty tray with parts; ","")&IF(AND(B8="Loaded",K8<>""),"second part: type Mixed; ","")&IF(AND(Q8<>"",N(Q8)>1),"over 100 % of the spec load; ","")&IF(N(R8)>Settings!$B$10,"over the tray maximum (kg); ","")&IF(AND(K8<>"",IFERROR(INDEX(Parts!$C$6:$C$45,MATCH(K8,Parts!$A$6:$A$45,0)),O8)<>O8),"different processes in one tray; ","")&IF(AND(S8<>"",T8=""),"rework reason missing; ",""))
A9: =IF(B9="","",COUNTA(B$7:B9)) -> 3 | B9: Loaded | D9: =IF(B9="","",IF(D8="",Report!$B$12,D8)) -> 9 | E9: =IF(B9="","",IF(C9<>"",C9,E8+D8/1440+SUMIFS(Holds!$F$7:$F$46,Holds!$B$7:$B$46,">="&E8,Holds!$B$7:$B$46,"<"&E8+D8/1440)/1440)) -> 46320.262 | F9: EX-1001 | G9: B-102 | H9: H-5521 | I9: C7 | J9: 60 | O9: =IF(F9="","",IFERROR(INDEX(Parts!$C$6:$C$45,MATCH(F9,Parts!$A$6:$A$45,0)),"")) -> HT | P9: =IF(F9="","",IFERROR(INDEX(Parts!$E$6:$E$45,MATCH(F9,Parts!$A$6:$A$45,0)),"")) -> 60 | Q9: =IF(OR(J9="",P9="",P9=0),"",J9/P9+IF(OR(N9="",K9=""),0,IFERROR(N9/INDEX(Parts!$E$6:$E$45,MATCH(K9,Parts!$A$6:$A$45,0)),0))) -> 1 | R9: =IF(B9="","",IF(J9="",0,J9*IFERROR(INDEX(Parts!$F$6:$F$45,MATCH(F9,Parts!$A$6:$A$45,0)),0))+IF(N9="",0,N9*IFERROR(INDEX(Parts!$F$6:$F$45,MATCH(K9,Parts!$A$6:$A$45,0)),0))) -> 108 | U9: =IF(B9="","",IF(F9="",Settings!$B$9,IFERROR(INDEX(Parts!$H$6:$H$45,MATCH(F9,Parts!$A$6:$A$45,0))+0,Settings!$B$9))) -> 18 | V9: =IF(B9="","",IF(INDEX($E$7:$E$336,ROW()-6+Settings!$B$7)<>"",INDEX($E$7:$E$336,ROW()-6+Settings!$B$7),E9+Settings!$B$7*D9/1440)) -> 46320.348 | W9: =IF(B9="","",IF(INDEX($E$7:$E$336,ROW()-6+Settings!$B$7+Settings!$B$8)<>"",INDEX($E$7:$E$336,ROW()-6+Settings!$B$7+Settings!$B$8),E9+(Settings!$B$7+Settings!$B$8)*D9/1440)+U9/1440) -> 46320.472 | X9: =IF(B9="","",IF(INDEX($E$7:$E$336,ROW()-6+Settings!$B$7+Settings!$B$8)<>"","line","estimate")) -> line | Y9: =IF(B9="","",INT(W9-Settings!$B$6)) -> 46320 | AA9: =IF(B9="","",IF(AND(B9<>"Empty",F9=""),"part missing; ","")&IF(AND(F9<>"",J9=""),"pieces missing; ","")&IF(AND(F9<>"",O9=""),"part not on the Parts sheet; ","")&IF(AND(B9="Empty",OR(F9<>"",K9<>"")),"empty tray with parts; ","")&IF(AND(B9="Loaded",K9<>""),"second part: type Mixed; ","")&IF(AND(Q9<>"",N(Q9)>1),"over 100 % of the spec load; ","")&IF(N(R9)>Settings!$B$10,"over the tray maximum (kg); ","")&IF(AND(K9<>"",IFERROR(INDEX(Parts!$C$6:$C$45,MATCH(K9,Parts!$A$6:$A$45,0)),O9)<>O9),"different processes in one tray; ","")&IF(AND(S9<>"",T9=""),"rework reason missing; ",""))
A10: =IF(B10="","",COUNTA(B$7:B10)) -> 4 | B10: Loaded | D10: =IF(B10="","",IF(D9="",Report!$B$12,D9)) -> 9 | E10: =IF(B10="","",IF(C10<>"",C10,E9+D9/1440+SUMIFS(Holds!$F$7:$F$46,Holds!$B$7:$B$46,">="&E9,Holds!$B$7:$B$46,"<"&E9+D9/1440)/1440)) -> 46320.269 | F10: EX-1001 | G10: B-102 | H10: H-5521 | I10: C7 | J10: 60 | O10: =IF(F10="","",IFERROR(INDEX(Parts!$C$6:$C$45,MATCH(F10,Parts!$A$6:$A$45,0)),"")) -> HT | P10: =IF(F10="","",IFERROR(INDEX(Parts!$E$6:$E$45,MATCH(F10,Parts!$A$6:$A$45,0)),"")) -> 60 | Q10: =IF(OR(J10="",P10="",P10=0),"",J10/P10+IF(OR(N10="",K10=""),0,IFERROR(N10/INDEX(Parts!$E$6:$E$45,MATCH(K10,Parts!$A$6:$A$45,0)),0))) -> 1 | R10: =IF(B10="","",IF(J10="",0,J10*IFERROR(INDEX(Parts!$F$6:$F$45,MATCH(F10,Parts!$A$6:$A$45,0)),0))+IF(N10="",0,N10*IFERROR(INDEX(Parts!$F$6:$F$45,MATCH(K10,Parts!$A$6:$A$45,0)),0))) -> 108 | U10: =IF(B10="","",IF(F10="",Settings!$B$9,IFERROR(INDEX(Parts!$H$6:$H$45,MATCH(F10,Parts!$A$6:$A$45,0))+0,Settings!$B$9))) -> 18 | V10: =IF(B10="","",IF(INDEX($E$7:$E$336,ROW()-6+Settings!$B$7)<>"",INDEX($E$7:$E$336,ROW()-6+Settings!$B$7),E10+Settings!$B$7*D10/1440)) -> 46320.355 | W10: =IF(B10="","",IF(INDEX($E$7:$E$336,ROW()-6+Settings!$B$7+Settings!$B$8)<>"",INDEX($E$7:$E$336,ROW()-6+Settings!$B$7+Settings!$B$8),E10+(Settings!$B$7+Settings!$B$8)*D10/1440)+U10/1440) -> 46320.478 | X10: =IF(B10="","",IF(INDEX($E$7:$E$336,ROW()-6+Settings!$B$7+Settings!$B$8)<>"","line","estimate")) -> line | Y10: =IF(B10="","",INT(W10-Settings!$B$6)) -> 46320 | AA10: =IF(B10="","",IF(AND(B10<>"Empty",F10=""),"part missing; ","")&IF(AND(F10<>"",J10=""),"pieces missing; ","")&IF(AND(F10<>"",O10=""),"part not on the Parts sheet; ","")&IF(AND(B10="Empty",OR(F10<>"",K10<>"")),"empty tray with parts; ","")&IF(AND(B10="Loaded",K10<>""),"second part: type Mixed; ","")&IF(AND(Q10<>"",N(Q10)>1),"over 100 % of the spec load; ","")&IF(N(R10)>Settings!$B$10,"over the tray maximum (kg); ","")&IF(AND(K10<>"",IFERROR(INDEX(Parts!$C$6:$C$45,MATCH(K10,Parts!$A$6:$A$45,0)),O10)<>O10),"different processes in one tray; ","")&IF(AND(S10<>"",T10=""),"rework reason missing; ",""))
A11: =IF(B11="","",COUNTA(B$7:B11)) -> 5 | B11: Loaded | D11: =IF(B11="","",IF(D10="",Report!$B$12,D10)) -> 9 | E11: =IF(B11="","",IF(C11<>"",C11,E10+D10/1440+SUMIFS(Holds!$F$7:$F$46,Holds!$B$7:$B$46,">="&E10,Holds!$B$7:$B$46,"<"&E10+D10/1440)/1440)) -> 46320.275 | F11: EX-1001 | G11: B-102 | H11: H-5521 | I11: C7 | J11: 60 | O11: =IF(F11="","",IFERROR(INDEX(Parts!$C$6:$C$45,MATCH(F11,Parts!$A$6:$A$45,0)),"")) -> HT | P11: =IF(F11="","",IFERROR(INDEX(Parts!$E$6:$E$45,MATCH(F11,Parts!$A$6:$A$45,0)),"")) -> 60 | Q11: =IF(OR(J11="",P11="",P11=0),"",J11/P11+IF(OR(N11="",K11=""),0,IFERROR(N11/INDEX(Parts!$E$6:$E$45,MATCH(K11,Parts!$A$6:$A$45,0)),0))) -> 1 | R11: =IF(B11="","",IF(J11="",0,J11*IFERROR(INDEX(Parts!$F$6:$F$45,MATCH(F11,Parts!$A$6:$A$45,0)),0))+IF(N11="",0,N11*IFERROR(INDEX(Parts!$F$6:$F$45,MATCH(K11,Parts!$A$6:$A$45,0)),0))) -> 108 | U11: =IF(B11="","",IF(F11="",Settings!$B$9,IFERROR(INDEX(Parts!$H$6:$H$45,MATCH(F11,Parts!$A$6:$A$45,0))+0,Settings!$B$9))) -> 18 | V11: =IF(B11="","",IF(INDEX($E$7:$E$336,ROW()-6+Settings!$B$7)<>"",INDEX($E$7:$E$336,ROW()-6+Settings!$B$7),E11+Settings!$B$7*D11/1440)) -> 46320.362 | W11: =IF(B11="","",IF(INDEX($E$7:$E$336,ROW()-6+Settings!$B$7+Settings!$B$8)<>"",INDEX($E$7:$E$336,ROW()-6+Settings!$B$7+Settings!$B$8),E11+(Settings!$B$7+Settings!$B$8)*D11/1440)+U11/1440) -> 46320.485 | X11: =IF(B11="","",IF(INDEX($E$7:$E$336,ROW()-6+Settings!$B$7+Settings!$B$8)<>"","line","estimate")) -> line | Y11: =IF(B11="","",INT(W11-Settings!$B$6)) -> 46320 | AA11: =IF(B11="","",IF(AND(B11<>"Empty",F11=""),"part missing; ","")&IF(AND(F11<>"",J11=""),"pieces missing; ","")&IF(AND(F11<>"",O11=""),"part not on the Parts sheet; ","")&IF(AND(B11="Empty",OR(F11<>"",K11<>"")),"empty tray with parts; ","")&IF(AND(B11="Loaded",K11<>""),"second part: type Mixed; ","")&IF(AND(Q11<>"",N(Q11)>1),"over 100 % of the spec load; ","")&IF(N(R11)>Settings!$B$10,"over the tray maximum (kg); ","")&IF(AND(K11<>"",IFERROR(INDEX(Parts!$C$6:$C$45,MATCH(K11,Parts!$A$6:$A$45,0)),O11)<>O11),"different processes in one tray; ","")&IF(AND(S11<>"",T11=""),"rework reason missing; ",""))
A12: =IF(B12="","",COUNTA(B$7:B12)) -> 6 | B12: Loaded | D12: =IF(B12="","",IF(D11="",Report!$B$12,D11)) -> 9 | E12: =IF(B12="","",IF(C12<>"",C12,E11+D11/1440+SUMIFS(Holds!$F$7:$F$46,Holds!$B$7:$B$46,">="&E11,Holds!$B$7:$B$46,"<"&E11+D11/1440)/1440)) -> 46320.281 | F12: EX-1001 | G12: B-102 | H12: H-5521 | I12: C7 | J12: 60 | O12: =IF(F12="","",IFERROR(INDEX(Parts!$C$6:$C$45,MATCH(F12,Parts!$A$6:$A$45,0)),"")) -> HT | P12: =IF(F12="","",IFERROR(INDEX(Parts!$E$6:$E$45,MATCH(F12,Parts!$A$6:$A$45,0)),"")) -> 60 | Q12: =IF(OR(J12="",P12="",P12=0),"",J12/P12+IF(OR(N12="",K12=""),0,IFERROR(N12/INDEX(Parts!$E$6:$E$45,MATCH(K12,Parts!$A$6:$A$45,0)),0))) -> 1 | R12: =IF(B12="","",IF(J12="",0,J12*IFERROR(INDEX(Parts!$F$6:$F$45,MATCH(F12,Parts!$A$6:$A$45,0)),0))+IF(N12="",0,N12*IFERROR(INDEX(Parts!$F$6:$F$45,MATCH(K12,Parts!$A$6:$A$45,0)),0))) -> 108 | U12: =IF(B12="","",IF(F12="",Settings!$B$9,IFERROR(INDEX(Parts!$H$6:$H$45,MATCH(F12,Parts!$A$6:$A$45,0))+0,Settings!$B$9))) -> 18 | V12: =IF(B12="","",IF(INDEX($E$7:$E$336,ROW()-6+Settings!$B$7)<>"",INDEX($E$7:$E$336,ROW()-6+Settings!$B$7),E12+Settings!$B$7*D12/1440)) -> 46320.369 | W12: =IF(B12="","",IF(INDEX($E$7:$E$336,ROW()-6+Settings!$B$7+Settings!$B$8)<>"",INDEX($E$7:$E$336,ROW()-6+Settings!$B$7+Settings!$B$8),E12+(Settings!$B$7+Settings!$B$8)*D12/1440)+U12/1440) -> 46320.492 | X12: =IF(B12="","",IF(INDEX($E$7:$E$336,ROW()-6+Settings!$B$7+Settings!$B$8)<>"","line","estimate")) -> line | Y12: =IF(B12="","",INT(W12-Settings!$B$6)) -> 46320 | AA12: =IF(B12="","",IF(AND(B12<>"Empty",F12=""),"part missing; ","")&IF(AND(F12<>"",J12=""),"pieces missing; ","")&IF(AND(F12<>"",O12=""),"part not on the Parts sheet; ","")&IF(AND(B12="Empty",OR(F12<>"",K12<>"")),"empty tray with parts; ","")&IF(AND(B12="Loaded",K12<>""),"second part: type Mixed; ","")&IF(AND(Q12<>"",N(Q12)>1),"over 100 % of the spec load; ","")&IF(N(R12)>Settings!$B$10,"over the tray maximum (kg); ","")&IF(AND(K12<>"",IFERROR(INDEX(Parts!$C$6:$C$45,MATCH(K12,Parts!$A$6:$A$45,0)),O12)<>O12),"different processes in one tray; ","")&IF(AND(S12<>"",T12=""),"rework reason missing; ",""))
A13: =IF(B13="","",COUNTA(B$7:B13)) -> 7 | B13: Loaded | D13: =IF(B13="","",IF(D12="",Report!$B$12,D12)) -> 9 | E13: =IF(B13="","",IF(C13<>"",C13,E12+D12/1440+SUMIFS(Holds!$F$7:$F$46,Holds!$B$7:$B$46,">="&E12,Holds!$B$7:$B$46,"<"&E12+D12/1440)/1440)) -> 46320.287 | F13: EX-1001 | G13: B-102 | H13: H-5521 | I13: C7 | J13: 60 | O13: =IF(F13="","",IFERROR(INDEX(Parts!$C$6:$C$45,MATCH(F13,Parts!$A$6:$A$45,0)),"")) -> HT | P13: =IF(F13="","",IFERROR(INDEX(Parts!$E$6:$E$45,MATCH(F13,Parts!$A$6:$A$45,0)),"")) -> 60 | Q13: =IF(OR(J13="",P13="",P13=0),"",J13/P13+IF(OR(N13="",K13=""),0,IFERROR(N13/INDEX(Parts!$E$6:$E$45,MATCH(K13,Parts!$A$6:$A$45,0)),0))) -> 1 | R13: =IF(B13="","",IF(J13="",0,J13*IFERROR(INDEX(Parts!$F$6:$F$45,MATCH(F13,Parts!$A$6:$A$45,0)),0))+IF(N13="",0,N13*IFERROR(INDEX(Parts!$F$6:$F$45,MATCH(K13,Parts!$A$6:$A$45,0)),0))) -> 108 | U13: =IF(B13="","",IF(F13="",Settings!$B$9,IFERROR(INDEX(Parts!$H$6:$H$45,MATCH(F13,Parts!$A$6:$A$45,0))+0,Settings!$B$9))) -> 18 | V13: =IF(B13="","",IF(INDEX($E$7:$E$336,ROW()-6+Settings!$B$7)<>"",INDEX($E$7:$E$336,ROW()-6+Settings!$B$7),E13+Settings!$B$7*D13/1440)) -> 46320.403 | W13: =IF(B13="","",IF(INDEX($E$7:$E$336,ROW()-6+Settings!$B$7+Settings!$B$8)<>"",INDEX($E$7:$E$336,ROW()-6+Settings!$B$7+Settings!$B$8),E13+(Settings!$B$7+Settings!$B$8)*D13/1440)+U13/1440) -> 46320.499 | X13: =IF(B13="","",IF(INDEX($E$7:$E$336,ROW()-6+Settings!$B$7+Settings!$B$8)<>"","line","estimate")) -> line | Y13: =IF(B13="","",INT(W13-Settings!$B$6)) -> 46320 | AA13: =IF(B13="","",IF(AND(B13<>"Empty",F13=""),"part missing; ","")&IF(AND(F13<>"",J13=""),"pieces missing; ","")&IF(AND(F13<>"",O13=""),"part not on the Parts sheet; ","")&IF(AND(B13="Empty",OR(F13<>"",K13<>"")),"empty tray with parts; ","")&IF(AND(B13="Loaded",K13<>""),"second part: type Mixed; ","")&IF(AND(Q13<>"",N(Q13)>1),"over 100 % of the spec load; ","")&IF(N(R13)>Settings!$B$10,"over the tray maximum (kg); ","")&IF(AND(K13<>"",IFERROR(INDEX(Parts!$C$6:$C$45,MATCH(K13,Parts!$A$6:$A$45,0)),O13)<>O13),"different processes in one tray; ","")&IF(AND(S13<>"",T13=""),"rework reason missing; ",""))
A14: =IF(B14="","",COUNTA(B$7:B14)) -> 8 | B14: Loaded | D14: =IF(B14="","",IF(D13="",Report!$B$12,D13)) -> 9 | E14: =IF(B14="","",IF(C14<>"",C14,E13+D13/1440+SUMIFS(Holds!$F$7:$F$46,Holds!$B$7:$B$46,">="&E13,Holds!$B$7:$B$46,"<"&E13+D13/1440)/1440)) -> 46320.294 | F14: EX-1001 | G14: B-102 | H14: H-5521 | I14: C7 | J14: 60 | O14: =IF(F14="","",IFERROR(INDEX(Parts!$C$6:$C$45,MATCH(F14,Parts!$A$6:$A$45,0)),"")) -> HT | P14: =IF(F14="","",IFERROR(INDEX(Parts!$E$6:$E$45,MATCH(F14,Parts!$A$6:$A$45,0)),"")) -> 60 | Q14: =IF(OR(J14="",P14="",P14=0),"",J14/P14+IF(OR(N14="",K14=""),0,IFERROR(N14/INDEX(Parts!$E$6:$E$45,MATCH(K14,Parts!$A$6:$A$45,0)),0))) -> 1 | R14: =IF(B14="","",IF(J14="",0,J14*IFERROR(INDEX(Parts!$F$6:$F$45,MATCH(F14,Parts!$A$6:$A$45,0)),0))+IF(N14="",0,N14*IFERROR(INDEX(Parts!$F$6:$F$45,MATCH(K14,Parts!$A$6:$A$45,0)),0))) -> 108 | U14: =IF(B14="","",IF(F14="",Settings!$B$9,IFERROR(INDEX(Parts!$H$6:$H$45,MATCH(F14,Parts!$A$6:$A$45,0))+0,Settings!$B$9))) -> 18 | V14: =IF(B14="","",IF(INDEX($E$7:$E$336,ROW()-6+Settings!$B$7)<>"",INDEX($E$7:$E$336,ROW()-6+Settings!$B$7),E14+Settings!$B$7*D14/1440)) -> 46320.41 | W14: =IF(B14="","",IF(INDEX($E$7:$E$336,ROW()-6+Settings!$B$7+Settings!$B$8)<>"",INDEX($E$7:$E$336,ROW()-6+Settings!$B$7+Settings!$B$8),E14+(Settings!$B$7+Settings!$B$8)*D14/1440)+U14/1440) -> 46320.506 | X14: =IF(B14="","",IF(INDEX($E$7:$E$336,ROW()-6+Settings!$B$7+Settings!$B$8)<>"","line","estimate")) -> line | Y14: =IF(B14="","",INT(W14-Settings!$B$6)) -> 46320 | AA14: =IF(B14="","",IF(AND(B14<>"Empty",F14=""),"part missing; ","")&IF(AND(F14<>"",J14=""),"pieces missing; ","")&IF(AND(F14<>"",O14=""),"part not on the Parts sheet; ","")&IF(AND(B14="Empty",OR(F14<>"",K14<>"")),"empty tray with parts; ","")&IF(AND(B14="Loaded",K14<>""),"second part: type Mixed; ","")&IF(AND(Q14<>"",N(Q14)>1),"over 100 % of the spec load; ","")&IF(N(R14)>Settings!$B$10,"over the tray maximum (kg); ","")&IF(AND(K14<>"",IFERROR(INDEX(Parts!$C$6:$C$45,MATCH(K14,Parts!$A$6:$A$45,0)),O14)<>O14),"different processes in one tray; ","")&IF(AND(S14<>"",T14=""),"rework reason missing; ",""))
A15: =IF(B15="","",COUNTA(B$7:B15)) -> 9 | B15: Loaded | D15: =IF(B15="","",IF(D14="",Report!$B$12,D14)) -> 9 | E15: =IF(B15="","",IF(C15<>"",C15,E14+D14/1440+SUMIFS(Holds!$F$7:$F$46,Holds!$B$7:$B$46,">="&E14,Holds!$B$7:$B$46,"<"&E14+D14/1440)/1440)) -> 46320.3 | F15: EX-1001 | G15: B-102 | H15: H-5521 | I15: C7 | J15: 60 | O15: =IF(F15="","",IFERROR(INDEX(Parts!$C$6:$C$45,MATCH(F15,Parts!$A$6:$A$45,0)),"")) -> HT | P15: =IF(F15="","",IFERROR(INDEX(Parts!$E$6:$E$45,MATCH(F15,Parts!$A$6:$A$45,0)),"")) -> 60 | Q15: =IF(OR(J15="",P15="",P15=0),"",J15/P15+IF(OR(N15="",K15=""),0,IFERROR(N15/INDEX(Parts!$E$6:$E$45,MATCH(K15,Parts!$A$6:$A$45,0)),0))) -> 1 | R15: =IF(B15="","",IF(J15="",0,J15*IFERROR(INDEX(Parts!$F$6:$F$45,MATCH(F15,Parts!$A$6:$A$45,0)),0))+IF(N15="",0,N15*IFERROR(INDEX(Parts!$F$6:$F$45,MATCH(K15,Parts!$A$6:$A$45,0)),0))) -> 108 | U15: =IF(B15="","",IF(F15="",Settings!$B$9,IFERROR(INDEX(Parts!$H$6:$H$45,MATCH(F15,Parts!$A$6:$A$45,0))+0,Settings!$B$9))) -> 18 | V15: =IF(B15="","",IF(INDEX($E$7:$E$336,ROW()-6+Settings!$B$7)<>"",INDEX($E$7:$E$336,ROW()-6+Settings!$B$7),E15+Settings!$B$7*D15/1440)) -> 46320.417 | W15: =IF(B15="","",IF(INDEX($E$7:$E$336,ROW()-6+Settings!$B$7+Settings!$B$8)<>"",INDEX($E$7:$E$336,ROW()-6+Settings!$B$7+Settings!$B$8),E15+(Settings!$B$7+Settings!$B$8)*D15/1440)+U15/1440) -> 46320.513 | X15: =IF(B15="","",IF(INDEX($E$7:$E$336,ROW()-6+Settings!$B$7+Settings!$B$8)<>"","line","estimate")) -> line | Y15: =IF(B15="","",INT(W15-Settings!$B$6)) -> 46320 | AA15: =IF(B15="","",IF(AND(B15<>"Empty",F15=""),"part missing; ","")&IF(AND(F15<>"",J15=""),"pieces missing; ","")&IF(AND(F15<>"",O15=""),"part not on the Parts sheet; ","")&IF(AND(B15="Empty",OR(F15<>"",K15<>"")),"empty tray with parts; ","")&IF(AND(B15="Loaded",K15<>""),"second part: type Mixed; ","")&IF(AND(Q15<>"",N(Q15)>1),"over 100 % of the spec load; ","")&IF(N(R15)>Settings!$B$10,"over the tray maximum (kg); ","")&IF(AND(K15<>"",IFERROR(INDEX(Parts!$C$6:$C$45,MATCH(K15,Parts!$A$6:$A$45,0)),O15)<>O15),"different processes in one tray; ","")&IF(AND(S15<>"",T15=""),"rework reason missing; ",""))
A16: =IF(B16="","",COUNTA(B$7:B16)) -> 10 | B16: Loaded | D16: 10 | E16: =IF(B16="","",IF(C16<>"",C16,E15+D15/1440+SUMIFS(Holds!$F$7:$F$46,Holds!$B$7:$B$46,">="&E15,Holds!$B$7:$B$46,"<"&E15+D15/1440)/1440)) -> 46320.306 | F16: EX-1001 | G16: B-102 | H16: H-5521 | I16: C7 | J16: 60 | O16: =IF(F16="","",IFERROR(INDEX(Parts!$C$6:$C$45,MATCH(F16,Parts!$A$6:$A$45,0)),"")) -> HT | P16: =IF(F16="","",IFERROR(INDEX(Parts!$E$6:$E$45,MATCH(F16,Parts!$A$6:$A$45,0)),"")) -> 60 | Q16: =IF(OR(J16="",P16="",P16=0),"",J16/P16+IF(OR(N16="",K16=""),0,IFERROR(N16/INDEX(Parts!$E$6:$E$45,MATCH(K16,Parts!$A$6:$A$45,0)),0))) -> 1 | R16: =IF(B16="","",IF(J16="",0,J16*IFERROR(INDEX(Parts!$F$6:$F$45,MATCH(F16,Parts!$A$6:$A$45,0)),0))+IF(N16="",0,N16*IFERROR(INDEX(Parts!$F$6:$F$45,MATCH(K16,Parts!$A$6:$A$45,0)),0))) -> 108 | U16: =IF(B16="","",IF(F16="",Settings!$B$9,IFERROR(INDEX(Parts!$H$6:$H$45,MATCH(F16,Parts!$A$6:$A$45,0))+0,Settings!$B$9))) -> 18 | V16: =IF(B16="","",IF(INDEX($E$7:$E$336,ROW()-6+Settings!$B$7)<>"",INDEX($E$7:$E$336,ROW()-6+Settings!$B$7),E16+Settings!$B$7*D16/1440)) -> 46320.424 | W16: =IF(B16="","",IF(INDEX($E$7:$E$336,ROW()-6+Settings!$B$7+Settings!$B$8)<>"",INDEX($E$7:$E$336,ROW()-6+Settings!$B$7+Settings!$B$8),E16+(Settings!$B$7+Settings!$B$8)*D16/1440)+U16/1440) -> 46320.52 | X16: =IF(B16="","",IF(INDEX($E$7:$E$336,ROW()-6+Settings!$B$7+Settings!$B$8)<>"","line","estimate")) -> line | Y16: =IF(B16="","",INT(W16-Settings!$B$6)) -> 46320 | Z16: Push changed 9 → 10 min (example) | AA16: =IF(B16="","",IF(AND(B16<>"Empty",F16=""),"part missing; ","")&IF(AND(F16<>"",J16=""),"pieces missing; ","")&IF(AND(F16<>"",O16=""),"part not on the Parts sheet; ","")&IF(AND(B16="Empty",OR(F16<>"",K16<>"")),"empty tray with parts; ","")&IF(AND(B16="Loaded",K16<>""),"second part: type Mixed; ","")&IF(AND(Q16<>"",N(Q16)>1),"over 100 % of the spec load; ","")&IF(N(R16)>Settings!$B$10,"over the tray maximum (kg); ","")&IF(AND(K16<>"",IFERROR(INDEX(Parts!$C$6:$C$45,MATCH(K16,Parts!$A$6:$A$45,0)),O16)<>O16),"different processes in one tray; ","")&IF(AND(S16<>"",T16=""),"rework reason missing; ",""))
A17: =IF(B17="","",COUNTA(B$7:B17)) -> 11 | B17: Loaded | D17: =IF(B17="","",IF(D16="",Report!$B$12,D16)) -> 10 | E17: =IF(B17="","",IF(C17<>"",C17,E16+D16/1440+SUMIFS(Holds!$F$7:$F$46,Holds!$B$7:$B$46,">="&E16,Holds!$B$7:$B$46,"<"&E16+D16/1440)/1440)) -> 46320.313 | F17: EX-1001 | G17: B-102 | H17: H-5521 | I17: C7 | J17: 60 | O17: =IF(F17="","",IFERROR(INDEX(Parts!$C$6:$C$45,MATCH(F17,Parts!$A$6:$A$45,0)),"")) -> HT | P17: =IF(F17="","",IFERROR(INDEX(Parts!$E$6:$E$45,MATCH(F17,Parts!$A$6:$A$45,0)),"")) -> 60 | Q17: =IF(OR(J17="",P17="",P17=0),"",J17/P17+IF(OR(N17="",K17=""),0,IFERROR(N17/INDEX(Parts!$E$6:$E$45,MATCH(K17,Parts!$A$6:$A$45,0)),0))) -> 1 | R17: =IF(B17="","",IF(J17="",0,J17*IFERROR(INDEX(Parts!$F$6:$F$45,MATCH(F17,Parts!$A$6:$A$45,0)),0))+IF(N17="",0,N17*IFERROR(INDEX(Parts!$F$6:$F$45,MATCH(K17,Parts!$A$6:$A$45,0)),0))) -> 108 | U17: =IF(B17="","",IF(F17="",Settings!$B$9,IFERROR(INDEX(Parts!$H$6:$H$45,MATCH(F17,Parts!$A$6:$A$45,0))+0,Settings!$B$9))) -> 18 | V17: =IF(B17="","",IF(INDEX($E$7:$E$336,ROW()-6+Settings!$B$7)<>"",INDEX($E$7:$E$336,ROW()-6+Settings!$B$7),E17+Settings!$B$7*D17/1440)) -> 46320.431 | W17: =IF(B17="","",IF(INDEX($E$7:$E$336,ROW()-6+Settings!$B$7+Settings!$B$8)<>"",INDEX($E$7:$E$336,ROW()-6+Settings!$B$7+Settings!$B$8),E17+(Settings!$B$7+Settings!$B$8)*D17/1440)+U17/1440) -> 46320.527 | X17: =IF(B17="","",IF(INDEX($E$7:$E$336,ROW()-6+Settings!$B$7+Settings!$B$8)<>"","line","estimate")) -> line | Y17: =IF(B17="","",INT(W17-Settings!$B$6)) -> 46320 | AA17: =IF(B17="","",IF(AND(B17<>"Empty",F17=""),"part missing; ","")&IF(AND(F17<>"",J17=""),"pieces missing; ","")&IF(AND(F17<>"",O17=""),"part not on the Parts sheet; ","")&IF(AND(B17="Empty",OR(F17<>"",K17<>"")),"empty tray with parts; ","")&IF(AND(B17="Loaded",K17<>""),"second part: type Mixed; ","")&IF(AND(Q17<>"",N(Q17)>1),"over 100 % of the spec load; ","")&IF(N(R17)>Settings!$B$10,"over the tray maximum (kg); ","")&IF(AND(K17<>"",IFERROR(INDEX(Parts!$C$6:$C$45,MATCH(K17,Parts!$A$6:$A$45,0)),O17)<>O17),"different processes in one tray; ","")&IF(AND(S17<>"",T17=""),"rework reason missing; ",""))
A18: =IF(B18="","",COUNTA(B$7:B18)) -> 12 | B18: Loaded | D18: =IF(B18="","",IF(D17="",Report!$B$12,D17)) -> 10 | E18: =IF(B18="","",IF(C18<>"",C18,E17+D17/1440+SUMIFS(Holds!$F$7:$F$46,Holds!$B$7:$B$46,">="&E17,Holds!$B$7:$B$46,"<"&E17+D17/1440)/1440)) -> 46320.32 | F18: EX-1001 | G18: B-102 | H18: H-5521 | I18: C7 | J18: 60 | O18: =IF(F18="","",IFERROR(INDEX(Parts!$C$6:$C$45,MATCH(F18,Parts!$A$6:$A$45,0)),"")) -> HT | P18: =IF(F18="","",IFERROR(INDEX(Parts!$E$6:$E$45,MATCH(F18,Parts!$A$6:$A$45,0)),"")) -> 60 | Q18: =IF(OR(J18="",P18="",P18=0),"",J18/P18+IF(OR(N18="",K18=""),0,IFERROR(N18/INDEX(Parts!$E$6:$E$45,MATCH(K18,Parts!$A$6:$A$45,0)),0))) -> 1 | R18: =IF(B18="","",IF(J18="",0,J18*IFERROR(INDEX(Parts!$F$6:$F$45,MATCH(F18,Parts!$A$6:$A$45,0)),0))+IF(N18="",0,N18*IFERROR(INDEX(Parts!$F$6:$F$45,MATCH(K18,Parts!$A$6:$A$45,0)),0))) -> 108 | U18: =IF(B18="","",IF(F18="",Settings!$B$9,IFERROR(INDEX(Parts!$H$6:$H$45,MATCH(F18,Parts!$A$6:$A$45,0))+0,Settings!$B$9))) -> 18 | V18: =IF(B18="","",IF(INDEX($E$7:$E$336,ROW()-6+Settings!$B$7)<>"",INDEX($E$7:$E$336,ROW()-6+Settings!$B$7),E18+Settings!$B$7*D18/1440)) -> 46320.438 | W18: =IF(B18="","",IF(INDEX($E$7:$E$336,ROW()-6+Settings!$B$7+Settings!$B$8)<>"",INDEX($E$7:$E$336,ROW()-6+Settings!$B$7+Settings!$B$8),E18+(Settings!$B$7+Settings!$B$8)*D18/1440)+U18/1440) -> 46320.534 | X18: =IF(B18="","",IF(INDEX($E$7:$E$336,ROW()-6+Settings!$B$7+Settings!$B$8)<>"","line","estimate")) -> line | Y18: =IF(B18="","",INT(W18-Settings!$B$6)) -> 46320 | AA18: =IF(B18="","",IF(AND(B18<>"Empty",F18=""),"part missing; ","")&IF(AND(F18<>"",J18=""),"pieces missing; ","")&IF(AND(F18<>"",O18=""),"part not on the Parts sheet; ","")&IF(AND(B18="Empty",OR(F18<>"",K18<>"")),"empty tray with parts; ","")&IF(AND(B18="Loaded",K18<>""),"second part: type Mixed; ","")&IF(AND(Q18<>"",N(Q18)>1),"over 100 % of the spec load; ","")&IF(N(R18)>Settings!$B$10,"over the tray maximum (kg); ","")&IF(AND(K18<>"",IFERROR(INDEX(Parts!$C$6:$C$45,MATCH(K18,Parts!$A$6:$A$45,0)),O18)<>O18),"different processes in one tray; ","")&IF(AND(S18<>"",T18=""),"rework reason missing; ",""))
A19: =IF(B19="","",COUNTA(B$7:B19)) -> 13 | B19: Loaded | D19: =IF(B19="","",IF(D18="",Report!$B$12,D18)) -> 10 | E19: =IF(B19="","",IF(C19<>"",C19,E18+D18/1440+SUMIFS(Holds!$F$7:$F$46,Holds!$B$7:$B$46,">="&E18,Holds!$B$7:$B$46,"<"&E18+D18/1440)/1440)) -> 46320.327 | F19: EX-1001 | G19: B-102 | H19: H-5521 | I19: C7 | J19: 60 | O19: =IF(F19="","",IFERROR(INDEX(Parts!$C$6:$C$45,MATCH(F19,Parts!$A$6:$A$45,0)),"")) -> HT | P19: =IF(F19="","",IFERROR(INDEX(Parts!$E$6:$E$45,MATCH(F19,Parts!$A$6:$A$45,0)),"")) -> 60 | Q19: =IF(OR(J19="",P19="",P19=0),"",J19/P19+IF(OR(N19="",K19=""),0,IFERROR(N19/INDEX(Parts!$E$6:$E$45,MATCH(K19,Parts!$A$6:$A$45,0)),0))) -> 1 | R19: =IF(B19="","",IF(J19="",0,J19*IFERROR(INDEX(Parts!$F$6:$F$45,MATCH(F19,Parts!$A$6:$A$45,0)),0))+IF(N19="",0,N19*IFERROR(INDEX(Parts!$F$6:$F$45,MATCH(K19,Parts!$A$6:$A$45,0)),0))) -> 108 | U19: =IF(B19="","",IF(F19="",Settings!$B$9,IFERROR(INDEX(Parts!$H$6:$H$45,MATCH(F19,Parts!$A$6:$A$45,0))+0,Settings!$B$9))) -> 18 | V19: =IF(B19="","",IF(INDEX($E$7:$E$336,ROW()-6+Settings!$B$7)<>"",INDEX($E$7:$E$336,ROW()-6+Settings!$B$7),E19+Settings!$B$7*D19/1440)) -> 46320.445 | W19: =IF(B19="","",IF(INDEX($E$7:$E$336,ROW()-6+Settings!$B$7+Settings!$B$8)<>"",INDEX($E$7:$E$336,ROW()-6+Settings!$B$7+Settings!$B$8),E19+(Settings!$B$7+Settings!$B$8)*D19/1440)+U19/1440) -> 46320.541 | X19: =IF(B19="","",IF(INDEX($E$7:$E$336,ROW()-6+Settings!$B$7+Settings!$B$8)<>"","line","estimate")) -> line | Y19: =IF(B19="","",INT(W19-Settings!$B$6)) -> 46320 | AA19: =IF(B19="","",IF(AND(B19<>"Empty",F19=""),"part missing; ","")&IF(AND(F19<>"",J19=""),"pieces missing; ","")&IF(AND(F19<>"",O19=""),"part not on the Parts sheet; ","")&IF(AND(B19="Empty",OR(F19<>"",K19<>"")),"empty tray with parts; ","")&IF(AND(B19="Loaded",K19<>""),"second part: type Mixed; ","")&IF(AND(Q19<>"",N(Q19)>1),"over 100 % of the spec load; ","")&IF(N(R19)>Settings!$B$10,"over the tray maximum (kg); ","")&IF(AND(K19<>"",IFERROR(INDEX(Parts!$C$6:$C$45,MATCH(K19,Parts!$A$6:$A$45,0)),O19)<>O19),"different processes in one tray; ","")&IF(AND(S19<>"",T19=""),"rework reason missing; ",""))
A20: =IF(B20="","",COUNTA(B$7:B20)) -> 14 | B20: Loaded | D20: =IF(B20="","",IF(D19="",Report!$B$12,D19)) -> 10 | E20: =IF(B20="","",IF(C20<>"",C20,E19+D19/1440+SUMIFS(Holds!$F$7:$F$46,Holds!$B$7:$B$46,">="&E19,Holds!$B$7:$B$46,"<"&E19+D19/1440)/1440)) -> 46320.334 | F20: EX-1001 | G20: B-102 | H20: H-5521 | I20: C7 | J20: 60 | O20: =IF(F20="","",IFERROR(INDEX(Parts!$C$6:$C$45,MATCH(F20,Parts!$A$6:$A$45,0)),"")) -> HT | P20: =IF(F20="","",IFERROR(INDEX(Parts!$E$6:$E$45,MATCH(F20,Parts!$A$6:$A$45,0)),"")) -> 60 | Q20: =IF(OR(J20="",P20="",P20=0),"",J20/P20+IF(OR(N20="",K20=""),0,IFERROR(N20/INDEX(Parts!$E$6:$E$45,MATCH(K20,Parts!$A$6:$A$45,0)),0))) -> 1 | R20: =IF(B20="","",IF(J20="",0,J20*IFERROR(INDEX(Parts!$F$6:$F$45,MATCH(F20,Parts!$A$6:$A$45,0)),0))+IF(N20="",0,N20*IFERROR(INDEX(Parts!$F$6:$F$45,MATCH(K20,Parts!$A$6:$A$45,0)),0))) -> 108 | U20: =IF(B20="","",IF(F20="",Settings!$B$9,IFERROR(INDEX(Parts!$H$6:$H$45,MATCH(F20,Parts!$A$6:$A$45,0))+0,Settings!$B$9))) -> 18 | V20: =IF(B20="","",IF(INDEX($E$7:$E$336,ROW()-6+Settings!$B$7)<>"",INDEX($E$7:$E$336,ROW()-6+Settings!$B$7),E20+Settings!$B$7*D20/1440)) -> 46320.452 | W20: =IF(B20="","",IF(INDEX($E$7:$E$336,ROW()-6+Settings!$B$7+Settings!$B$8)<>"",INDEX($E$7:$E$336,ROW()-6+Settings!$B$7+Settings!$B$8),E20+(Settings!$B$7+Settings!$B$8)*D20/1440)+U20/1440) -> 46320.548 | X20: =IF(B20="","",IF(INDEX($E$7:$E$336,ROW()-6+Settings!$B$7+Settings!$B$8)<>"","line","estimate")) -> line | Y20: =IF(B20="","",INT(W20-Settings!$B$6)) -> 46320 | AA20: =IF(B20="","",IF(AND(B20<>"Empty",F20=""),"part missing; ","")&IF(AND(F20<>"",J20=""),"pieces missing; ","")&IF(AND(F20<>"",O20=""),"part not on the Parts sheet; ","")&IF(AND(B20="Empty",OR(F20<>"",K20<>"")),"empty tray with parts; ","")&IF(AND(B20="Loaded",K20<>""),"second part: type Mixed; ","")&IF(AND(Q20<>"",N(Q20)>1),"over 100 % of the spec load; ","")&IF(N(R20)>Settings!$B$10,"over the tray maximum (kg); ","")&IF(AND(K20<>"",IFERROR(INDEX(Parts!$C$6:$C$45,MATCH(K20,Parts!$A$6:$A$45,0)),O20)<>O20),"different processes in one tray; ","")&IF(AND(S20<>"",T20=""),"rework reason missing; ",""))
A21: =IF(B21="","",COUNTA(B$7:B21)) -> 15 | B21: Empty | D21: =IF(B21="","",IF(D20="",Report!$B$12,D20)) -> 10 | E21: =IF(B21="","",IF(C21<>"",C21,E20+D20/1440+SUMIFS(Holds!$F$7:$F$46,Holds!$B$7:$B$46,">="&E20,Holds!$B$7:$B$46,"<"&E20+D20/1440)/1440)) -> 46320.341 | O21: =IF(F21="","",IFERROR(INDEX(Parts!$C$6:$C$45,MATCH(F21,Parts!$A$6:$A$45,0)),"")) | P21: =IF(F21="","",IFERROR(INDEX(Parts!$E$6:$E$45,MATCH(F21,Parts!$A$6:$A$45,0)),"")) | Q21: =IF(OR(J21="",P21="",P21=0),"",J21/P21+IF(OR(N21="",K21=""),0,IFERROR(N21/INDEX(Parts!$E$6:$E$45,MATCH(K21,Parts!$A$6:$A$45,0)),0))) | R21: =IF(B21="","",IF(J21="",0,J21*IFERROR(INDEX(Parts!$F$6:$F$45,MATCH(F21,Parts!$A$6:$A$45,0)),0))+IF(N21="",0,N21*IFERROR(INDEX(Parts!$F$6:$F$45,MATCH(K21,Parts!$A$6:$A$45,0)),0))) -> 0 | U21: =IF(B21="","",IF(F21="",Settings!$B$9,IFERROR(INDEX(Parts!$H$6:$H$45,MATCH(F21,Parts!$A$6:$A$45,0))+0,Settings!$B$9))) -> 18 | V21: =IF(B21="","",IF(INDEX($E$7:$E$336,ROW()-6+Settings!$B$7)<>"",INDEX($E$7:$E$336,ROW()-6+Settings!$B$7),E21+Settings!$B$7*D21/1440)) -> 46320.459 | W21: =IF(B21="","",IF(INDEX($E$7:$E$336,ROW()-6+Settings!$B$7+Settings!$B$8)<>"",INDEX($E$7:$E$336,ROW()-6+Settings!$B$7+Settings!$B$8),E21+(Settings!$B$7+Settings!$B$8)*D21/1440)+U21/1440) -> 46320.555 | X21: =IF(B21="","",IF(INDEX($E$7:$E$336,ROW()-6+Settings!$B$7+Settings!$B$8)<>"","line","estimate")) -> line | Y21: =IF(B21="","",INT(W21-Settings!$B$6)) -> 46320 | AA21: =IF(B21="","",IF(AND(B21<>"Empty",F21=""),"part missing; ","")&IF(AND(F21<>"",J21=""),"pieces missing; ","")&IF(AND(F21<>"",O21=""),"part not on the Parts sheet; ","")&IF(AND(B21="Empty",OR(F21<>"",K21<>"")),"empty tray with parts; ","")&IF(AND(B21="Loaded",K21<>""),"second part: type Mixed; ","")&IF(AND(Q21<>"",N(Q21)>1),"over 100 % of the spec load; ","")&IF(N(R21)>Settings!$B$10,"over the tray maximum (kg); ","")&IF(AND(K21<>"",IFERROR(INDEX(Parts!$C$6:$C$45,MATCH(K21,Parts!$A$6:$A$45,0)),O21)<>O21),"different processes in one tray; ","")&IF(AND(S21<>"",T21=""),"rework reason missing; ",""))
A22: =IF(B22="","",COUNTA(B$7:B22)) -> 16 | B22: Loaded | D22: =IF(B22="","",IF(D21="",Report!$B$12,D21)) -> 10 | E22: =IF(B22="","",IF(C22<>"",C22,E21+D21/1440+SUMIFS(Holds!$F$7:$F$46,Holds!$B$7:$B$46,">="&E21,Holds!$B$7:$B$46,"<"&E21+D21/1440)/1440)) -> 46320.348 | F22: EX-3001 | G22: B-215 | H22: H-5590 | I22: N/A | J22: 30 | O22: =IF(F22="","",IFERROR(INDEX(Parts!$C$6:$C$45,MATCH(F22,Parts!$A$6:$A$45,0)),"")) -> NORM | P22: =IF(F22="","",IFERROR(INDEX(Parts!$E$6:$E$45,MATCH(F22,Parts!$A$6:$A$45,0)),"")) -> 30 | Q22: =IF(OR(J22="",P22="",P22=0),"",J22/P22+IF(OR(N22="",K22=""),0,IFERROR(N22/INDEX(Parts!$E$6:$E$45,MATCH(K22,Parts!$A$6:$A$45,0)),0))) -> 1 | R22: =IF(B22="","",IF(J22="",0,J22*IFERROR(INDEX(Parts!$F$6:$F$45,MATCH(F22,Parts!$A$6:$A$45,0)),0))+IF(N22="",0,N22*IFERROR(INDEX(Parts!$F$6:$F$45,MATCH(K22,Parts!$A$6:$A$45,0)),0))) -> 66 | U22: =IF(B22="","",IF(F22="",Settings!$B$9,IFERROR(INDEX(Parts!$H$6:$H$45,MATCH(F22,Parts!$A$6:$A$45,0))+0,Settings!$B$9))) -> 18 | V22: =IF(B22="","",IF(INDEX($E$7:$E$336,ROW()-6+Settings!$B$7)<>"",INDEX($E$7:$E$336,ROW()-6+Settings!$B$7),E22+Settings!$B$7*D22/1440)) -> 46320.466 | W22: =IF(B22="","",IF(INDEX($E$7:$E$336,ROW()-6+Settings!$B$7+Settings!$B$8)<>"",INDEX($E$7:$E$336,ROW()-6+Settings!$B$7+Settings!$B$8),E22+(Settings!$B$7+Settings!$B$8)*D22/1440)+U22/1440) -> 46320.562 | X22: =IF(B22="","",IF(INDEX($E$7:$E$336,ROW()-6+Settings!$B$7+Settings!$B$8)<>"","line","estimate")) -> line | Y22: =IF(B22="","",INT(W22-Settings!$B$6)) -> 46320 | AA22: =IF(B22="","",IF(AND(B22<>"Empty",F22=""),"part missing; ","")&IF(AND(F22<>"",J22=""),"pieces missing; ","")&IF(AND(F22<>"",O22=""),"part not on the Parts sheet; ","")&IF(AND(B22="Empty",OR(F22<>"",K22<>"")),"empty tray with parts; ","")&IF(AND(B22="Loaded",K22<>""),"second part: type Mixed; ","")&IF(AND(Q22<>"",N(Q22)>1),"over 100 % of the spec load; ","")&IF(N(R22)>Settings!$B$10,"over the tray maximum (kg); ","")&IF(AND(K22<>"",IFERROR(INDEX(Parts!$C$6:$C$45,MATCH(K22,Parts!$A$6:$A$45,0)),O22)<>O22),"different processes in one tray; ","")&IF(AND(S22<>"",T22=""),"rework reason missing; ",""))
A23: =IF(B23="","",COUNTA(B$7:B23)) -> 17 | B23: Loaded | D23: =IF(B23="","",IF(D22="",Report!$B$12,D22)) -> 10 | E23: =IF(B23="","",IF(C23<>"",C23,E22+D22/1440+SUMIFS(Holds!$F$7:$F$46,Holds!$B$7:$B$46,">="&E22,Holds!$B$7:$B$46,"<"&E22+D22/1440)/1440)) -> 46320.355 | F23: EX-3001 | G23: B-215 | H23: H-5590 | I23: N/A | J23: 30 | O23: =IF(F23="","",IFERROR(INDEX(Parts!$C$6:$C$45,MATCH(F23,Parts!$A$6:$A$45,0)),"")) -> NORM | P23: =IF(F23="","",IFERROR(INDEX(Parts!$E$6:$E$45,MATCH(F23,Parts!$A$6:$A$45,0)),"")) -> 30 | Q23: =IF(OR(J23="",P23="",P23=0),"",J23/P23+IF(OR(N23="",K23=""),0,IFERROR(N23/INDEX(Parts!$E$6:$E$45,MATCH(K23,Parts!$A$6:$A$45,0)),0))) -> 1 | R23: =IF(B23="","",IF(J23="",0,J23*IFERROR(INDEX(Parts!$F$6:$F$45,MATCH(F23,Parts!$A$6:$A$45,0)),0))+IF(N23="",0,N23*IFERROR(INDEX(Parts!$F$6:$F$45,MATCH(K23,Parts!$A$6:$A$45,0)),0))) -> 66 | U23: =IF(B23="","",IF(F23="",Settings!$B$9,IFERROR(INDEX(Parts!$H$6:$H$45,MATCH(F23,Parts!$A$6:$A$45,0))+0,Settings!$B$9))) -> 18 | V23: =IF(B23="","",IF(INDEX($E$7:$E$336,ROW()-6+Settings!$B$7)<>"",INDEX($E$7:$E$336,ROW()-6+Settings!$B$7),E23+Settings!$B$7*D23/1440)) -> 46320.473 | W23: =IF(B23="","",IF(INDEX($E$7:$E$336,ROW()-6+Settings!$B$7+Settings!$B$8)<>"",INDEX($E$7:$E$336,ROW()-6+Settings!$B$7+Settings!$B$8),E23+(Settings!$B$7+Settings!$B$8)*D23/1440)+U23/1440) -> 46320.569 | X23: =IF(B23="","",IF(INDEX($E$7:$E$336,ROW()-6+Settings!$B$7+Settings!$B$8)<>"","line","estimate")) -> line | Y23: =IF(B23="","",INT(W23-Settings!$B$6)) -> 46320 | AA23: =IF(B23="","",IF(AND(B23<>"Empty",F23=""),"part missing; ","")&IF(AND(F23<>"",J23=""),"pieces missing; ","")&IF(AND(F23<>"",O23=""),"part not on the Parts sheet; ","")&IF(AND(B23="Empty",OR(F23<>"",K23<>"")),"empty tray with parts; ","")&IF(AND(B23="Loaded",K23<>""),"second part: type Mixed; ","")&IF(AND(Q23<>"",N(Q23)>1),"over 100 % of the spec load; ","")&IF(N(R23)>Settings!$B$10,"over the tray maximum (kg); ","")&IF(AND(K23<>"",IFERROR(INDEX(Parts!$C$6:$C$45,MATCH(K23,Parts!$A$6:$A$45,0)),O23)<>O23),"different processes in one tray; ","")&IF(AND(S23<>"",T23=""),"rework reason missing; ",""))
A24: =IF(B24="","",COUNTA(B$7:B24)) -> 18 | B24: Loaded | D24: =IF(B24="","",IF(D23="",Report!$B$12,D23)) -> 10 | E24: =IF(B24="","",IF(C24<>"",C24,E23+D23/1440+SUMIFS(Holds!$F$7:$F$46,Holds!$B$7:$B$46,">="&E23,Holds!$B$7:$B$46,"<"&E23+D23/1440)/1440)) -> 46320.362 | F24: EX-3001 | G24: B-215 | H24: H-5590 | I24: N/A | J24: 30 | O24: =IF(F24="","",IFERROR(INDEX(Parts!$C$6:$C$45,MATCH(F24,Parts!$A$6:$A$45,0)),"")) -> NORM | P24: =IF(F24="","",IFERROR(INDEX(Parts!$E$6:$E$45,MATCH(F24,Parts!$A$6:$A$45,0)),"")) -> 30 | Q24: =IF(OR(J24="",P24="",P24=0),"",J24/P24+IF(OR(N24="",K24=""),0,IFERROR(N24/INDEX(Parts!$E$6:$E$45,MATCH(K24,Parts!$A$6:$A$45,0)),0))) -> 1 | R24: =IF(B24="","",IF(J24="",0,J24*IFERROR(INDEX(Parts!$F$6:$F$45,MATCH(F24,Parts!$A$6:$A$45,0)),0))+IF(N24="",0,N24*IFERROR(INDEX(Parts!$F$6:$F$45,MATCH(K24,Parts!$A$6:$A$45,0)),0))) -> 66 | U24: =IF(B24="","",IF(F24="",Settings!$B$9,IFERROR(INDEX(Parts!$H$6:$H$45,MATCH(F24,Parts!$A$6:$A$45,0))+0,Settings!$B$9))) -> 18 | V24: =IF(B24="","",IF(INDEX($E$7:$E$336,ROW()-6+Settings!$B$7)<>"",INDEX($E$7:$E$336,ROW()-6+Settings!$B$7),E24+Settings!$B$7*D24/1440)) -> 46320.48 | W24: =IF(B24="","",IF(INDEX($E$7:$E$336,ROW()-6+Settings!$B$7+Settings!$B$8)<>"",INDEX($E$7:$E$336,ROW()-6+Settings!$B$7+Settings!$B$8),E24+(Settings!$B$7+Settings!$B$8)*D24/1440)+U24/1440) -> 46320.576 | X24: =IF(B24="","",IF(INDEX($E$7:$E$336,ROW()-6+Settings!$B$7+Settings!$B$8)<>"","line","estimate")) -> line | Y24: =IF(B24="","",INT(W24-Settings!$B$6)) -> 46320 | AA24: =IF(B24="","",IF(AND(B24<>"Empty",F24=""),"part missing; ","")&IF(AND(F24<>"",J24=""),"pieces missing; ","")&IF(AND(F24<>"",O24=""),"part not on the Parts sheet; ","")&IF(AND(B24="Empty",OR(F24<>"",K24<>"")),"empty tray with parts; ","")&IF(AND(B24="Loaded",K24<>""),"second part: type Mixed; ","")&IF(AND(Q24<>"",N(Q24)>1),"over 100 % of the spec load; ","")&IF(N(R24)>Settings!$B$10,"over the tray maximum (kg); ","")&IF(AND(K24<>"",IFERROR(INDEX(Parts!$C$6:$C$45,MATCH(K24,Parts!$A$6:$A$45,0)),O24)<>O24),"different processes in one tray; ","")&IF(AND(S24<>"",T24=""),"rework reason missing; ",""))
A25: =IF(B25="","",COUNTA(B$7:B25)) -> 19 | B25: Loaded | D25: =IF(B25="","",IF(D24="",Report!$B$12,D24)) -> 10 | E25: =IF(B25="","",IF(C25<>"",C25,E24+D24/1440+SUMIFS(Holds!$F$7:$F$46,Holds!$B$7:$B$46,">="&E24,Holds!$B$7:$B$46,"<"&E24+D24/1440)/1440)) -> 46320.369 | F25: EX-3001 | G25: B-215 | H25: H-5590 | I25: N/A | J25: 30 | O25: =IF(F25="","",IFERROR(INDEX(Parts!$C$6:$C$45,MATCH(F25,Parts!$A$6:$A$45,0)),"")) -> NORM | P25: =IF(F25="","",IFERROR(INDEX(Parts!$E$6:$E$45,MATCH(F25,Parts!$A$6:$A$45,0)),"")) -> 30 | Q25: =IF(OR(J25="",P25="",P25=0),"",J25/P25+IF(OR(N25="",K25=""),0,IFERROR(N25/INDEX(Parts!$E$6:$E$45,MATCH(K25,Parts!$A$6:$A$45,0)),0))) -> 1 | R25: =IF(B25="","",IF(J25="",0,J25*IFERROR(INDEX(Parts!$F$6:$F$45,MATCH(F25,Parts!$A$6:$A$45,0)),0))+IF(N25="",0,N25*IFERROR(INDEX(Parts!$F$6:$F$45,MATCH(K25,Parts!$A$6:$A$45,0)),0))) -> 66 | U25: =IF(B25="","",IF(F25="",Settings!$B$9,IFERROR(INDEX(Parts!$H$6:$H$45,MATCH(F25,Parts!$A$6:$A$45,0))+0,Settings!$B$9))) -> 18 | V25: =IF(B25="","",IF(INDEX($E$7:$E$336,ROW()-6+Settings!$B$7)<>"",INDEX($E$7:$E$336,ROW()-6+Settings!$B$7),E25+Settings!$B$7*D25/1440)) -> 46320.487 | W25: =IF(B25="","",IF(INDEX($E$7:$E$336,ROW()-6+Settings!$B$7+Settings!$B$8)<>"",INDEX($E$7:$E$336,ROW()-6+Settings!$B$7+Settings!$B$8),E25+(Settings!$B$7+Settings!$B$8)*D25/1440)+U25/1440) -> 46320.583 | X25: =IF(B25="","",IF(INDEX($E$7:$E$336,ROW()-6+Settings!$B$7+Settings!$B$8)<>"","line","estimate")) -> line | Y25: =IF(B25="","",INT(W25-Settings!$B$6)) -> 46320 | AA25: =IF(B25="","",IF(AND(B25<>"Empty",F25=""),"part missing; ","")&IF(AND(F25<>"",J25=""),"pieces missing; ","")&IF(AND(F25<>"",O25=""),"part not on the Parts sheet; ","")&IF(AND(B25="Empty",OR(F25<>"",K25<>"")),"empty tray with parts; ","")&IF(AND(B25="Loaded",K25<>""),"second part: type Mixed; ","")&IF(AND(Q25<>"",N(Q25)>1),"over 100 % of the spec load; ","")&IF(N(R25)>Settings!$B$10,"over the tray maximum (kg); ","")&IF(AND(K25<>"",IFERROR(INDEX(Parts!$C$6:$C$45,MATCH(K25,Parts!$A$6:$A$45,0)),O25)<>O25),"different processes in one tray; ","")&IF(AND(S25<>"",T25=""),"rework reason missing; ",""))
A26: =IF(B26="","",COUNTA(B$7:B26)) -> 20 | B26: Loaded | D26: =IF(B26="","",IF(D25="",Report!$B$12,D25)) -> 10 | E26: =IF(B26="","",IF(C26<>"",C26,E25+D25/1440+SUMIFS(Holds!$F$7:$F$46,Holds!$B$7:$B$46,">="&E25,Holds!$B$7:$B$46,"<"&E25+D25/1440)/1440)) -> 46320.403 | F26: EX-3001 | G26: B-215 | H26: H-5590 | I26: N/A | J26: 30 | O26: =IF(F26="","",IFERROR(INDEX(Parts!$C$6:$C$45,MATCH(F26,Parts!$A$6:$A$45,0)),"")) -> NORM | P26: =IF(F26="","",IFERROR(INDEX(Parts!$E$6:$E$45,MATCH(F26,Parts!$A$6:$A$45,0)),"")) -> 30 | Q26: =IF(OR(J26="",P26="",P26=0),"",J26/P26+IF(OR(N26="",K26=""),0,IFERROR(N26/INDEX(Parts!$E$6:$E$45,MATCH(K26,Parts!$A$6:$A$45,0)),0))) -> 1 | R26: =IF(B26="","",IF(J26="",0,J26*IFERROR(INDEX(Parts!$F$6:$F$45,MATCH(F26,Parts!$A$6:$A$45,0)),0))+IF(N26="",0,N26*IFERROR(INDEX(Parts!$F$6:$F$45,MATCH(K26,Parts!$A$6:$A$45,0)),0))) -> 66 | U26: =IF(B26="","",IF(F26="",Settings!$B$9,IFERROR(INDEX(Parts!$H$6:$H$45,MATCH(F26,Parts!$A$6:$A$45,0))+0,Settings!$B$9))) -> 18 | V26: =IF(B26="","",IF(INDEX($E$7:$E$336,ROW()-6+Settings!$B$7)<>"",INDEX($E$7:$E$336,ROW()-6+Settings!$B$7),E26+Settings!$B$7*D26/1440)) -> 46320.494 | W26: =IF(B26="","",IF(INDEX($E$7:$E$336,ROW()-6+Settings!$B$7+Settings!$B$8)<>"",INDEX($E$7:$E$336,ROW()-6+Settings!$B$7+Settings!$B$8),E26+(Settings!$B$7+Settings!$B$8)*D26/1440)+U26/1440) -> 46320.59 | X26: =IF(B26="","",IF(INDEX($E$7:$E$336,ROW()-6+Settings!$B$7+Settings!$B$8)<>"","line","estimate")) -> line | Y26: =IF(B26="","",INT(W26-Settings!$B$6)) -> 46320 | AA26: =IF(B26="","",IF(AND(B26<>"Empty",F26=""),"part missing; ","")&IF(AND(F26<>"",J26=""),"pieces missing; ","")&IF(AND(F26<>"",O26=""),"part not on the Parts sheet; ","")&IF(AND(B26="Empty",OR(F26<>"",K26<>"")),"empty tray with parts; ","")&IF(AND(B26="Loaded",K26<>""),"second part: type Mixed; ","")&IF(AND(Q26<>"",N(Q26)>1),"over 100 % of the spec load; ","")&IF(N(R26)>Settings!$B$10,"over the tray maximum (kg); ","")&IF(AND(K26<>"",IFERROR(INDEX(Parts!$C$6:$C$45,MATCH(K26,Parts!$A$6:$A$45,0)),O26)<>O26),"different processes in one tray; ","")&IF(AND(S26<>"",T26=""),"rework reason missing; ",""))
A27: =IF(B27="","",COUNTA(B$7:B27)) -> 21 | B27: Loaded | D27: =IF(B27="","",IF(D26="",Report!$B$12,D26)) -> 10 | E27: =IF(B27="","",IF(C27<>"",C27,E26+D26/1440+SUMIFS(Holds!$F$7:$F$46,Holds!$B$7:$B$46,">="&E26,Holds!$B$7:$B$46,"<"&E26+D26/1440)/1440)) -> 46320.41 | F27: EX-3001 | G27: B-215 | H27: H-5590 | I27: N/A | J27: 30 | O27: =IF(F27="","",IFERROR(INDEX(Parts!$C$6:$C$45,MATCH(F27,Parts!$A$6:$A$45,0)),"")) -> NORM | P27: =IF(F27="","",IFERROR(INDEX(Parts!$E$6:$E$45,MATCH(F27,Parts!$A$6:$A$45,0)),"")) -> 30 | Q27: =IF(OR(J27="",P27="",P27=0),"",J27/P27+IF(OR(N27="",K27=""),0,IFERROR(N27/INDEX(Parts!$E$6:$E$45,MATCH(K27,Parts!$A$6:$A$45,0)),0))) -> 1 | R27: =IF(B27="","",IF(J27="",0,J27*IFERROR(INDEX(Parts!$F$6:$F$45,MATCH(F27,Parts!$A$6:$A$45,0)),0))+IF(N27="",0,N27*IFERROR(INDEX(Parts!$F$6:$F$45,MATCH(K27,Parts!$A$6:$A$45,0)),0))) -> 66 | U27: =IF(B27="","",IF(F27="",Settings!$B$9,IFERROR(INDEX(Parts!$H$6:$H$45,MATCH(F27,Parts!$A$6:$A$45,0))+0,Settings!$B$9))) -> 18 | V27: =IF(B27="","",IF(INDEX($E$7:$E$336,ROW()-6+Settings!$B$7)<>"",INDEX($E$7:$E$336,ROW()-6+Settings!$B$7),E27+Settings!$B$7*D27/1440)) -> 46320.501 | W27: =IF(B27="","",IF(INDEX($E$7:$E$336,ROW()-6+Settings!$B$7+Settings!$B$8)<>"",INDEX($E$7:$E$336,ROW()-6+Settings!$B$7+Settings!$B$8),E27+(Settings!$B$7+Settings!$B$8)*D27/1440)+U27/1440) -> 46320.597 | X27: =IF(B27="","",IF(INDEX($E$7:$E$336,ROW()-6+Settings!$B$7+Settings!$B$8)<>"","line","estimate")) -> estimate | Y27: =IF(B27="","",INT(W27-Settings!$B$6)) -> 46320 | AA27: =IF(B27="","",IF(AND(B27<>"Empty",F27=""),"part missing; ","")&IF(AND(F27<>"",J27=""),"pieces missing; ","")&IF(AND(F27<>"",O27=""),"part not on the Parts sheet; ","")&IF(AND(B27="Empty",OR(F27<>"",K27<>"")),"empty tray with parts; ","")&IF(AND(B27="Loaded",K27<>""),"second part: type Mixed; ","")&IF(AND(Q27<>"",N(Q27)>1),"over 100 % of the spec load; ","")&IF(N(R27)>Settings!$B$10,"over the tray maximum (kg); ","")&IF(AND(K27<>"",IFERROR(INDEX(Parts!$C$6:$C$45,MATCH(K27,Parts!$A$6:$A$45,0)),O27)<>O27),"different processes in one tray; ","")&IF(AND(S27<>"",T27=""),"rework reason missing; ",""))
A28: =IF(B28="","",COUNTA(B$7:B28)) -> 22 | B28: Loaded | D28: =IF(B28="","",IF(D27="",Report!$B$12,D27)) -> 10 | E28: =IF(B28="","",IF(C28<>"",C28,E27+D27/1440+SUMIFS(Holds!$F$7:$F$46,Holds!$B$7:$B$46,">="&E27,Holds!$B$7:$B$46,"<"&E27+D27/1440)/1440)) -> 46320.417 | F28: EX-3001 | G28: B-215 | H28: H-5590 | I28: N/A | J28: 30 | O28: =IF(F28="","",IFERROR(INDEX(Parts!$C$6:$C$45,MATCH(F28,Parts!$A$6:$A$45,0)),"")) -> NORM | P28: =IF(F28="","",IFERROR(INDEX(Parts!$E$6:$E$45,MATCH(F28,Parts!$A$6:$A$45,0)),"")) -> 30 | Q28: =IF(OR(J28="",P28="",P28=0),"",J28/P28+IF(OR(N28="",K28=""),0,IFERROR(N28/INDEX(Parts!$E$6:$E$45,MATCH(K28,Parts!$A$6:$A$45,0)),0))) -> 1 | R28: =IF(B28="","",IF(J28="",0,J28*IFERROR(INDEX(Parts!$F$6:$F$45,MATCH(F28,Parts!$A$6:$A$45,0)),0))+IF(N28="",0,N28*IFERROR(INDEX(Parts!$F$6:$F$45,MATCH(K28,Parts!$A$6:$A$45,0)),0))) -> 66 | U28: =IF(B28="","",IF(F28="",Settings!$B$9,IFERROR(INDEX(Parts!$H$6:$H$45,MATCH(F28,Parts!$A$6:$A$45,0))+0,Settings!$B$9))) -> 18 | V28: =IF(B28="","",IF(INDEX($E$7:$E$336,ROW()-6+Settings!$B$7)<>"",INDEX($E$7:$E$336,ROW()-6+Settings!$B$7),E28+Settings!$B$7*D28/1440)) -> 46320.508 | W28: =IF(B28="","",IF(INDEX($E$7:$E$336,ROW()-6+Settings!$B$7+Settings!$B$8)<>"",INDEX($E$7:$E$336,ROW()-6+Settings!$B$7+Settings!$B$8),E28+(Settings!$B$7+Settings!$B$8)*D28/1440)+U28/1440) -> 46320.603 | X28: =IF(B28="","",IF(INDEX($E$7:$E$336,ROW()-6+Settings!$B$7+Settings!$B$8)<>"","line","estimate")) -> estimate | Y28: =IF(B28="","",INT(W28-Settings!$B$6)) -> 46320 | AA28: =IF(B28="","",IF(AND(B28<>"Empty",F28=""),"part missing; ","")&IF(AND(F28<>"",J28=""),"pieces missing; ","")&IF(AND(F28<>"",O28=""),"part not on the Parts sheet; ","")&IF(AND(B28="Empty",OR(F28<>"",K28<>"")),"empty tray with parts; ","")&IF(AND(B28="Loaded",K28<>""),"second part: type Mixed; ","")&IF(AND(Q28<>"",N(Q28)>1),"over 100 % of the spec load; ","")&IF(N(R28)>Settings!$B$10,"over the tray maximum (kg); ","")&IF(AND(K28<>"",IFERROR(INDEX(Parts!$C$6:$C$45,MATCH(K28,Parts!$A$6:$A$45,0)),O28)<>O28),"different processes in one tray; ","")&IF(AND(S28<>"",T28=""),"rework reason missing; ",""))
A29: =IF(B29="","",COUNTA(B$7:B29)) -> 23 | B29: Loaded | D29: =IF(B29="","",IF(D28="",Report!$B$12,D28)) -> 10 | E29: =IF(B29="","",IF(C29<>"",C29,E28+D28/1440+SUMIFS(Holds!$F$7:$F$46,Holds!$B$7:$B$46,">="&E28,Holds!$B$7:$B$46,"<"&E28+D28/1440)/1440)) -> 46320.424 | F29: EX-3001 | G29: B-215 | H29: H-5590 | I29: N/A | J29: 30 | O29: =IF(F29="","",IFERROR(INDEX(Parts!$C$6:$C$45,MATCH(F29,Parts!$A$6:$A$45,0)),"")) -> NORM | P29: =IF(F29="","",IFERROR(INDEX(Parts!$E$6:$E$45,MATCH(F29,Parts!$A$6:$A$45,0)),"")) -> 30 | Q29: =IF(OR(J29="",P29="",P29=0),"",J29/P29+IF(OR(N29="",K29=""),0,IFERROR(N29/INDEX(Parts!$E$6:$E$45,MATCH(K29,Parts!$A$6:$A$45,0)),0))) -> 1 | R29: =IF(B29="","",IF(J29="",0,J29*IFERROR(INDEX(Parts!$F$6:$F$45,MATCH(F29,Parts!$A$6:$A$45,0)),0))+IF(N29="",0,N29*IFERROR(INDEX(Parts!$F$6:$F$45,MATCH(K29,Parts!$A$6:$A$45,0)),0))) -> 66 | U29: =IF(B29="","",IF(F29="",Settings!$B$9,IFERROR(INDEX(Parts!$H$6:$H$45,MATCH(F29,Parts!$A$6:$A$45,0))+0,Settings!$B$9))) -> 18 | V29: =IF(B29="","",IF(INDEX($E$7:$E$336,ROW()-6+Settings!$B$7)<>"",INDEX($E$7:$E$336,ROW()-6+Settings!$B$7),E29+Settings!$B$7*D29/1440)) -> 46320.515 | W29: =IF(B29="","",IF(INDEX($E$7:$E$336,ROW()-6+Settings!$B$7+Settings!$B$8)<>"",INDEX($E$7:$E$336,ROW()-6+Settings!$B$7+Settings!$B$8),E29+(Settings!$B$7+Settings!$B$8)*D29/1440)+U29/1440) -> 46320.61 | X29: =IF(B29="","",IF(INDEX($E$7:$E$336,ROW()-6+Settings!$B$7+Settings!$B$8)<>"","line","estimate")) -> estimate | Y29: =IF(B29="","",INT(W29-Settings!$B$6)) -> 46320 | AA29: =IF(B29="","",IF(AND(B29<>"Empty",F29=""),"part missing; ","")&IF(AND(F29<>"",J29=""),"pieces missing; ","")&IF(AND(F29<>"",O29=""),"part not on the Parts sheet; ","")&IF(AND(B29="Empty",OR(F29<>"",K29<>"")),"empty tray with parts; ","")&IF(AND(B29="Loaded",K29<>""),"second part: type Mixed; ","")&IF(AND(Q29<>"",N(Q29)>1),"over 100 % of the spec load; ","")&IF(N(R29)>Settings!$B$10,"over the tray maximum (kg); ","")&IF(AND(K29<>"",IFERROR(INDEX(Parts!$C$6:$C$45,MATCH(K29,Parts!$A$6:$A$45,0)),O29)<>O29),"different processes in one tray; ","")&IF(AND(S29<>"",T29=""),"rework reason missing; ",""))
A30: =IF(B30="","",COUNTA(B$7:B30)) -> 24 | B30: Mixed | D30: =IF(B30="","",IF(D29="",Report!$B$12,D29)) -> 10 | E30: =IF(B30="","",IF(C30<>"",C30,E29+D29/1440+SUMIFS(Holds!$F$7:$F$46,Holds!$B$7:$B$46,">="&E29,Holds!$B$7:$B$46,"<"&E29+D29/1440)/1440)) -> 46320.431 | F30: EX-3001 | G30: B-215 | H30: H-5590 | I30: N/A | J30: 12 | K30: EX-3001 | L30: B-216 | M30: H-5591 | N30: 15 | O30: =IF(F30="","",IFERROR(INDEX(Parts!$C$6:$C$45,MATCH(F30,Parts!$A$6:$A$45,0)),"")) -> NORM | P30: =IF(F30="","",IFERROR(INDEX(Parts!$E$6:$E$45,MATCH(F30,Parts!$A$6:$A$45,0)),"")) -> 30 | Q30: =IF(OR(J30="",P30="",P30=0),"",J30/P30+IF(OR(N30="",K30=""),0,IFERROR(N30/INDEX(Parts!$E$6:$E$45,MATCH(K30,Parts!$A$6:$A$45,0)),0))) -> 0.9 | R30: =IF(B30="","",IF(J30="",0,J30*IFERROR(INDEX(Parts!$F$6:$F$45,MATCH(F30,Parts!$A$6:$A$45,0)),0))+IF(N30="",0,N30*IFERROR(INDEX(Parts!$F$6:$F$45,MATCH(K30,Parts!$A$6:$A$45,0)),0))) -> 59.4 | U30: =IF(B30="","",IF(F30="",Settings!$B$9,IFERROR(INDEX(Parts!$H$6:$H$45,MATCH(F30,Parts!$A$6:$A$45,0))+0,Settings!$B$9))) -> 18 | V30: =IF(B30="","",IF(INDEX($E$7:$E$336,ROW()-6+Settings!$B$7)<>"",INDEX($E$7:$E$336,ROW()-6+Settings!$B$7),E30+Settings!$B$7*D30/1440)) -> 46320.522 | W30: =IF(B30="","",IF(INDEX($E$7:$E$336,ROW()-6+Settings!$B$7+Settings!$B$8)<>"",INDEX($E$7:$E$336,ROW()-6+Settings!$B$7+Settings!$B$8),E30+(Settings!$B$7+Settings!$B$8)*D30/1440)+U30/1440) -> 46320.617 | X30: =IF(B30="","",IF(INDEX($E$7:$E$336,ROW()-6+Settings!$B$7+Settings!$B$8)<>"","line","estimate")) -> estimate | Y30: =IF(B30="","",INT(W30-Settings!$B$6)) -> 46320 | AA30: =IF(B30="","",IF(AND(B30<>"Empty",F30=""),"part missing; ","")&IF(AND(F30<>"",J30=""),"pieces missing; ","")&IF(AND(F30<>"",O30=""),"part not on the Parts sheet; ","")&IF(AND(B30="Empty",OR(F30<>"",K30<>"")),"empty tray with parts; ","")&IF(AND(B30="Loaded",K30<>""),"second part: type Mixed; ","")&IF(AND(Q30<>"",N(Q30)>1),"over 100 % of the spec load; ","")&IF(N(R30)>Settings!$B$10,"over the tray maximum (kg); ","")&IF(AND(K30<>"",IFERROR(INDEX(Parts!$C$6:$C$45,MATCH(K30,Parts!$A$6:$A$45,0)),O30)<>O30),"different processes in one tray; ","")&IF(AND(S30<>"",T30=""),"rework reason missing; ",""))
A31: =IF(B31="","",COUNTA(B$7:B31)) -> 25 | B31: Empty | D31: =IF(B31="","",IF(D30="",Report!$B$12,D30)) -> 10 | E31: =IF(B31="","",IF(C31<>"",C31,E30+D30/1440+SUMIFS(Holds!$F$7:$F$46,Holds!$B$7:$B$46,">="&E30,Holds!$B$7:$B$46,"<"&E30+D30/1440)/1440)) -> 46320.438 | O31: =IF(F31="","",IFERROR(INDEX(Parts!$C$6:$C$45,MATCH(F31,Parts!$A$6:$A$45,0)),"")) | P31: =IF(F31="","",IFERROR(INDEX(Parts!$E$6:$E$45,MATCH(F31,Parts!$A$6:$A$45,0)),"")) | Q31: =IF(OR(J31="",P31="",P31=0),"",J31/P31+IF(OR(N31="",K31=""),0,IFERROR(N31/INDEX(Parts!$E$6:$E$45,MATCH(K31,Parts!$A$6:$A$45,0)),0))) | R31: =IF(B31="","",IF(J31="",0,J31*IFERROR(INDEX(Parts!$F$6:$F$45,MATCH(F31,Parts!$A$6:$A$45,0)),0))+IF(N31="",0,N31*IFERROR(INDEX(Parts!$F$6:$F$45,MATCH(K31,Parts!$A$6:$A$45,0)),0))) -> 0 | U31: =IF(B31="","",IF(F31="",Settings!$B$9,IFERROR(INDEX(Parts!$H$6:$H$45,MATCH(F31,Parts!$A$6:$A$45,0))+0,Settings!$B$9))) -> 18 | V31: =IF(B31="","",IF(INDEX($E$7:$E$336,ROW()-6+Settings!$B$7)<>"",INDEX($E$7:$E$336,ROW()-6+Settings!$B$7),E31+Settings!$B$7*D31/1440)) -> 46320.528 | W31: =IF(B31="","",IF(INDEX($E$7:$E$336,ROW()-6+Settings!$B$7+Settings!$B$8)<>"",INDEX($E$7:$E$336,ROW()-6+Settings!$B$7+Settings!$B$8),E31+(Settings!$B$7+Settings!$B$8)*D31/1440)+U31/1440) -> 46320.624 | X31: =IF(B31="","",IF(INDEX($E$7:$E$336,ROW()-6+Settings!$B$7+Settings!$B$8)<>"","line","estimate")) -> estimate | Y31: =IF(B31="","",INT(W31-Settings!$B$6)) -> 46320 | AA31: =IF(B31="","",IF(AND(B31<>"Empty",F31=""),"part missing; ","")&IF(AND(F31<>"",J31=""),"pieces missing; ","")&IF(AND(F31<>"",O31=""),"part not on the Parts sheet; ","")&IF(AND(B31="Empty",OR(F31<>"",K31<>"")),"empty tray with parts; ","")&IF(AND(B31="Loaded",K31<>""),"second part: type Mixed; ","")&IF(AND(Q31<>"",N(Q31)>1),"over 100 % of the spec load; ","")&IF(N(R31)>Settings!$B$10,"over the tray maximum (kg); ","")&IF(AND(K31<>"",IFERROR(INDEX(Parts!$C$6:$C$45,MATCH(K31,Parts!$A$6:$A$45,0)),O31)<>O31),"different processes in one tray; ","")&IF(AND(S31<>"",T31=""),"rework reason missing; ",""))
